Workbook

Sheet README
A1: Hengli Hydraulics — Financial Model
A3: Company | B3: Jiangsu Hengli Hydraulic Co., Ltd.
A4: Ticker | B4: SSE:601100
A5: Reporting currency | B5: RMB (millions)
A6: Fiscal year end | B6: December 31
A7: Model date | B7: 2026-05-19
A8: Model author | B8: Equity Research Initiation — Task 2 (Financial Modeling)
A10: Data sources | B10: Audited consolidated FS from cninfo: FY2025 AR (2026-04-20), FY2023 AR (2024-04-22), FY2021 AR (2022-04-25). Segment & geo splits per FY2025 AR p.15–16 (top-5 customer & domestic/overseas).
A12: Tabs | B12: 1. Revenue Model — product (5) + geography (6) breakdowns, FY20A-FY30E
B13: 2. Income Statement — 40+ line items, FY20A-FY30E
B14: 3. Cash Flow Statement — CFO/CFI/CFF, FY20A-FY30E
B15: 4. Balance Sheet — FY22A-FY30E (older years partial)
B16: 5. Scenarios — Bull / Base / Bear comparison FY30E
B17: 6. DCF Inputs — unlevered FCF for Task 3 valuation
A19: Color coding | B19: BLUE = hardcoded input (change me); BLACK = formula; GREEN = cross-sheet link
A20: Projection shading | B20: Yellow = projected period (FY2026E–FY2030E)
A22: Caveats | B22: FY2020 / FY2021 balance-sheet detail not fully extracted (only 2 yrs of comparatives per Chinese AR).
B23: FY2022 BS extracted from FY2023 AR comparatives; certain BS sub-lines for FY2022/FY2023 estimated.
B24: Segment splits prior to FY2025 are management commentary-based estimates; FY2025 is audited.

Sheet Revenue Model
A1: HENGLI HYDRAULICS — REVENUE MODEL (RMB millions)
B3: FY2020A | C3: FY2021A | D3: FY2022A | E3: FY2023A | F3: FY2024A | G3: FY2025A | H3: FY2026E | I3: FY2027E | J3: FY2028E | K3: FY2029E | L3: FY2030E
A5: A. REVENUE BY PRODUCT SEGMENT
A6: Hydraulic cylinders (液压油缸) | B6: 3534 | C6: 4188 | D6: 3608 | E6: 4090 | F6: 4760 | G6: 5254 | H6: 5621.8 | I6: 6015.3 | J6: 6496.5 | K6: 6951.3 | L6: 7368.4
A7: YoY growth % | C7: =(C6/B6)-1 | D7: =(D6/C6)-1 | E7: =(E6/D6)-1 | F7: =(F6/E6)-1 | G7: =(G6/F6)-1 | H7: =(H6/G6)-1 | I7: =(I6/H6)-1 | J7: =(J6/I6)-1 | ... L7: =(L6/K6)-1
A8: — Excavator cylinders (~75% of segment) | B8: =B6*0.75 | C8: =C6*0.75 | D8: =D6*0.75 | E8: =E6*0.75 | F8: =F6*0.75 | G8: =G6*0.75 | H8: =H6*0.75 | I8: =I6*0.75 | ... L8: =L6*0.75
A9: — Non-excavator (AWP, marine, wind, etc.) | B9: =B6*0.25 | C9: =C6*0.25 | D9: =D6*0.25 | E9: =E6*0.25 | F9: =F6*0.25 | G9: =G6*0.25 | H9: =H6*0.25 | I9: =I6*0.25 | ... L9: =L6*0.25
A11: Hydraulic pumps, valves & motors | B11: 2517 | C11: 3010 | D11: 2780 | E11: 3050 | F11: 3585 | G11: 4326 | H11: 5018.2 | I11: 5770.9 | J11: 6521.1 | K11: 7303.6 | L11: 8034
A12: YoY growth % | C12: =(C11/B11)-1 | D12: =(D11/C11)-1 | E12: =(E11/D11)-1 | F12: =(F11/E11)-1 | G12: =(G11/F11)-1 | H12: =(H11/G11)-1 | I12: =(I11/H11)-1 | J12: =(J11/I11)-1 | ... L12: =(L11/K11)-1
A13: — Main pumps (excavator) | B13: =B11*0.55 | C13: =C11*0.55 | D13: =D11*0.55 | E13: =E11*0.55 | F13: =F11*0.55 | G13: =G11*0.55 | H13: =H11*0.55 | I13: =I11*0.55 | ... L13: =L11*0.55
A14: — Multi-way valves | B14: =B11*0.20 | C14: =C11*0.20 | D14: =D11*0.20 | E14: =E11*0.20 | F14: =F11*0.20 | G14: =G11*0.20 | H14: =H11*0.20 | I14: =I11*0.20 | ... L14: =L11*0.20
A15: — Travel/swing motors & industrial pumps | B15: =B11*0.25 | C15: =C11*0.25 | D15: =D11*0.25 | E15: =E11*0.25 | F15: =F11*0.25 | G15: =G11*0.25 | H15: =H11*0.25 | I15: =I11*0.25 | ... L15: =L11*0.25
A17: Hydraulic systems (TBM, marine, water) | B17: 350 | C17: 410 | D17: 340 | E17: 320 | F17: 296 | G17: 385 | H17: 454.3 | I17: 522.4 | J17: 585.1 | K17: 643.7 | L17: 695.1
A18: YoY growth % | C18: =(C17/B17)-1 | D18: =(D17/C17)-1 | E18: =(E17/D17)-1 | F18: =(F17/E17)-1 | G18: =(G17/F17)-1 | H18: =(H17/G17)-1 | I18: =(I17/H17)-1 | J18: =(J17/I17)-1 | ... L18: =(L17/K17)-1
A20: Components, castings & LINEAR-DRIVE (★ key catalyst) | B20: 800 | C20: 940 | D20: 850 | E20: 780 | F20: 684 | G20: 891 | H20: 1247.4 | I20: 1871.1 | J20: 2900.2 | K20: 4060.3 | L20: 5075.4
A21: YoY growth % | C21: =(C20/B20)-1 | D21: =(D20/C20)-1 | E21: =(E20/D20)-1 | F21: =(F20/E20)-1 | G21: =(G20/F20)-1 | H21: =(H20/G20)-1 | I21: =(I20/H20)-1 | J21: =(J20/I20)-1 | ... L21: =(L20/K20)-1
A22: — Linear-drive (ball/roller screws, guideways) — mgmt 3× to RMB ~300m FY26E | B22: 0 | C22: 0 | D22: 0 | E22: 0 | F22: 30 | G22: 100 | H22: 300 | I22: 600 | J22: 1100 | K22: 1700 | L22: 2300
A23: — Castings & traditional components | B23: =B20-B22 | C23: =C20-C22 | D23: =D20-D22 | E23: =E20-E22 | F23: =F20-F22 | G23: =G20-G22 | H23: =H20-H22 | I23: =I20-I22 | ... L23: =L20-L22
A25: Other revenue (reconciling) | B25: 654 | C25: 761.2 | D25: 618.7 | E25: 744.6 | F25: 64.7 | G25: 85 | H25: 89.2 | I25: 93.7 | J25: 97.5 | K25: 100.4 | L25: 103.4
A27: TOTAL REVENUE (sum of products) | B27: =B6+B11+B17+B20+B25 | C27: =C6+C11+C17+C20+C25 | D27: =D6+D11+D17+D20+D25 | E27: =E6+E11+E17+E20+E25 | F27: =F6+F11+F17+F20+F25 | G27: =G6+G11+G17+G20+G25 | H27: =H6+H11+H17+H20+H25 | I27: =I6+I11+I17+I20+I25 | ... L27: =L6+L11+L17+L20+L25
A28: Total revenue growth % | C28: =(C27/B27)-1 | D28: =(D27/C27)-1 | E28: =(E27/D27)-1 | F28: =(F27/E27)-1 | G28: =(G27/F27)-1 | H28: =(H27/G27)-1 | I28: =(I27/H27)-1 | J28: =(J27/I27)-1 | ... L28: =(L27/K27)-1
A30: Memo: reported audited revenue (historicals) | B30: 7855 | C30: 9309.2 | D30: 8196.7 | E30: 8984.6 | F30: 9389.7 | G30: 10941
A31: Variance vs sum-of-segments (%) | B31: =(B30-B27)/B30 | C31: =(C30-C27)/C30 | D31: =(D30-D27)/D30 | E31: =(E30-E27)/E30 | F31: =(F30-F27)/F30 | G31: =(G30-G27)/G30
A34: B. REVENUE BY GEOGRAPHY
A35: Greater China (domestic) | B35: 5800 | C35: 7000 | D35: 6100 | E35: 6800 | F35: 7250 | G35: 8750 | H35: 10150 | I35: 11672.5 | J35: 13306.7 | K35: 15036.5 | L35: 16840.9
A36: % of total revenue | B36: =B35/B27 | C36: =C35/C27 | D36: =D35/D27 | E36: =E35/E27 | F36: =F35/F27 | G36: =G35/G27 | H36: =H35/H27 | I36: =I35/I27 | ... L36: =L35/L27
A37: YoY % | C37: =(C35/B35)-1 | D37: =(D35/C35)-1 | E37: =(E35/D35)-1 | F37: =(F35/E35)-1 | G37: =(G35/F35)-1 | H37: =(H35/G35)-1 | I37: =(I35/H35)-1 | J37: =(J35/I35)-1 | ... L37: =(L35/K35)-1
A39: Overseas (total) | B39: 2055 | C39: 2309.2 | D39: 2096.7 | E39: 2184.6 | F39: 2139.7 | G39: 2110 | H39: 2489.8 | I39: 2987.8 | J39: 3525.6 | K39: 4054.4 | L39: 4540.9
A40: % of total revenue | B40: =B39/B27 | C40: =C39/C27 | D40: =D39/D27 | E40: =E39/E27 | F40: =F39/F27 | G40: =G39/G27 | H40: =H39/H27 | I40: =I39/I27 | ... L40: =L39/L27
A41: — Asia-Pacific (ex-China): Japan, India, Indonesia, S. Korea | B41: 900 | C41: 1000 | D41: 920 | E41: 950 | F41: 920 | G41: 850 | H41: 935 | I41: 1075.2 | J41: 1268.8 | K41: 1459.1 | L41: 1634.2
A42: — Europe: Germany, UK, Italy, France | B42: 550 | C42: 620 | D42: 580 | E42: 620 | F42: 600 | G42: 620 | H42: 669.6 | I42: 736.6 | J42: 810.2 | K42: 891.2 | L42: 962.5
A43: — North America: USA + Mexico ★ (Mexico ramp 2026-28) | B43: 500 | C43: 580 | D43: 510 | E43: 530 | F43: 540 | G43: 580 | H43: 754 | I43: 980.2 | J43: 1225.2 | K43: 1445.8 | L43: 1619.3
A44: — Rest of World (Brazil, Guinea, etc.) | B44: 105 | C44: 109.2 | D44: 86.7 | E44: 84.6 | F44: 79.7 | G44: 60 | H44: 66 | I44: 73.9 | J44: 82.8 | K44: 91.1 | L44: 98.4
A46: TOTAL REVENUE (sum by geography) | B46: =B35+B39 | C46: =C35+C39 | D46: =D35+D39 | E46: =E35+E39 | F46: =F35+F39 | G46: =G35+G39 | H46: =H35+H39 | I46: =I35+I39 | ... L46: =L35+L39
A48: C. REVENUE BY CHANNEL
A49: 100% direct OEM (no distribution layer) | B49: =B27 | C49: =C27 | D49: =D27 | E49: =E27 | F49: =F27 | G49: =G27 | H49: =H27 | I49: =I27 | ... L49: =L27
A50: Top-5 customer concentration (Cat, Sany, XCMG, Komatsu, Liugong) | B50: 3400 | C50: 4050 | D50: 3500 | E50: 3812 | F50: 4144 | G50: 4602 | H50: =H27*0.42 | I50: =I27*0.42 | J50: =J27*0.42 | K50: =K27*0.42 | L50: =L27*0.42
A51: Top-5 as % of revenue | B51: =B50/B27 | C51: =C50/C27 | D51: =D50/D27 | E51: =E50/E27 | F51: =F50/F27 | G51: =G50/G27 | H51: =H50/H27 | I51: =I50/I27 | ... L51: =L50/L27

Sheet Income Statement
A1: HENGLI HYDRAULICS — CONSOLIDATED INCOME STATEMENT (RMB millions)
B3: FY2020A | C3: FY2021A | D3: FY2022A | E3: FY2023A | F3: FY2024A | G3: FY2025A | H3: FY2026E | I3: FY2027E | J3: FY2028E | K3: FY2029E | L3: FY2030E
A5: Revenue | B5: ='Revenue Model'!B27 | C5: ='Revenue Model'!C27 | D5: ='Revenue Model'!D27 | E5: ='Revenue Model'!E27 | F5: ='Revenue Model'!F27 | G5: ='Revenue Model'!G27 | H5: ='Revenue Model'!H27 | I5: ='Revenue Model'!I27 | ... L5: ='Revenue Model'!L27
A6: YoY growth % | C6: =(C5/B5)-1 | D6: =(D5/C5)-1 | E6: =(E5/D5)-1 | F6: =(F5/E5)-1 | G6: =(G5/F5)-1 | H6: =(H5/G5)-1 | I6: =(I5/H5)-1 | J6: =(J5/I5)-1 | ... L6: =(L5/K5)-1
A8: Cost of revenue (COGS) | B8: 4391 | C8: 5211.9 | D8: 4872.7 | E8: 5220 | F8: 5368.2 | G8: 6392 | H8: =H5*(1-0.425) | I8: =I5*(1-0.43) | J8: =J5*(1-0.435) | K8: =K5*(1-0.435) | L8: =L5*(1-0.435)
A9: Gross profit | B9: =B5-B8 | C9: =C5-C8 | D9: =D5-D8 | E9: =E5-E8 | F9: =F5-F8 | G9: =G5-G8 | H9: =H5-H8 | I9: =I5-I8 | ... L9: =L5-L8
A10: Gross margin % | B10: =B9/B5 | C10: =C9/C5 | D10: =D9/D5 | E10: =E9/E5 | F10: =F9/F5 | G10: =G9/G5 | H10: =H9/H5 | I10: =I9/I5 | ... L10: =L9/L5
A12: Operating expenses
A13: Taxes & surcharges | B13: 72.1 | C13: 77.9 | D13: 71 | E13: 81.7 | F13: 90 | G13: 108.9 | H13: =H5*0.01 | I13: =I5*0.01 | J13: =J5*0.01 | K13: =K5*0.01 | L13: =L5*0.01
A14: Selling expense | B14: 106.9 | C14: 111.9 | D14: 123.6 | E14: 185.7 | F14: 217.1 | G14: 254.5 | H14: =H5*0.024 | I14: =I5*0.024 | J14: =J5*0.023 | K14: =K5*0.023 | L14: =L5*0.023
A15: % of revenue | B15: =B14/B5 | C15: =C14/C5 | D15: =D14/D5 | E15: =E14/E5 | F15: =F14/F5 | G15: =G14/G5 | H15: =H14/H5 | I15: =I14/I5 | ... L15: =L14/L5
A16: G&A expense | B16: 200 | C16: 226.9 | D16: 275.3 | E16: 404.4 | F16: 591.8 | G16: 649.3 | H16: =H5*0.06 | I16: =I5*0.058 | J16: =J5*0.055 | K16: =K5*0.053 | L16: =L5*0.052
A17: % of revenue | B17: =B16/B5 | C17: =C16/C5 | D17: =D16/D5 | E17: =E16/E5 | F17: =F16/F5 | G17: =G16/G5 | H17: =H16/H5 | I17: =I16/I5 | ... L17: =L16/L5
A18: R&D expense | B18: 308.6 | C18: 636.1 | D18: 650 | E18: 694.4 | F18: 727.7 | G18: 705 | H18: =H5*0.065 | I18: =I5*0.065 | J18: =J5*0.065 | K18: =K5*0.065 | L18: =L5*0.065
A19: % of revenue | B19: =B18/B5 | C19: =C18/C5 | D19: =D18/D5 | E19: =E18/E5 | F19: =F18/F5 | G19: =G18/G5 | H19: =H18/H5 | I19: =I18/I5 | ... L19: =L18/L5
A20: Financial expense (net interest) | B20: 151.3 | C20: 89.3 | D20: -332.4 | E20: -368.5 | F20: -131.4 | G20: 5.9 | H20: =H5*0.0 | I20: =I5*0.0 | J20: =J5*-0.005 | K20: =K5*-0.005 | L20: =L5*-0.005
A21: Total operating expenses (incl. taxes & financial) | B21: =B13+B14+B16+B18+B20 | C21: =C13+C14+C16+C18+C20 | D21: =D13+D14+D16+D18+D20 | E21: =E13+E14+E16+E18+E20 | F21: =F13+F14+F16+F18+F20 | G21: =G13+G14+G16+G18+G20 | H21: =H13+H14+H16+H18+H20 | I21: =I13+I14+I16+I18+I20 | ... L21: =L13+L14+L16+L18+L20
A23: Other operating items
A24: Other income (govt subsidies, R&D credits) | B24: 60.8 | C24: 131.9 | D24: 104.9 | E24: 113 | F24: 124.3 | G24: 89 | H24: 100 | I24: 110 | J24: 120 | K24: 130 | L24: 140
A25: Investment income (incl. JV, fund disposals) | B25: 10.6 | C25: 7 | D25: 13.9 | E25: 2 | F25: -1.2 | G25: 176.4 | H25: 120 | I25: 100 | J25: 80 | K25: 80 | L25: 80
A26: Fair value change (derivatives, hedges) | B26: 0 | C26: 10.3 | D26: 7.3 | E26: 0.7 | F26: 203.2 | G26: 92.4 | H26: 50 | I26: 30 | J26: 20 | K26: 20 | L26: 20
A27: Credit impairment (receivables) | B27: -37 | C27: 19.4 | D27: 9.5 | E27: -12.1 | F27: -12.9 | G27: -33 | H27: -40 | I27: -45 | J27: -50 | K27: -55 | L27: -60
A28: Asset impairment (inventory, fixed) | B28: -52.5 | C28: -66.7 | D28: -54.6 | E28: -56.1 | F28: -53.5 | G28: -106.6 | H28: -100 | I28: -110 | J28: -115 | K28: -120 | L28: -125
A29: Asset disposal gain/(loss) | B29: -0.8 | C29: -0.7 | D29: 0.3 | E29: 0.3 | F29: 0.2 | G29: 0.1 | H29: 0 | I29: 0 | J29: 0 | K29: 0 | L29: 0
A31: Operating profit (营业利润) | B31: =B9-B21+B24+B25+B26+B27+B28+B29 | C31: =C9-C21+C24+C25+C26+C27+C28+C29 | D31: =D9-D21+D24+D25+D26+D27+D28+D29 | E31: =E9-E21+E24+E25+E26+E27+E28+E29 | F31: =F9-F21+F24+F25+F26+F27+F28+F29 | G31: =G9-G21+G24+G25+G26+G27+G28+G29 | H31: =H9-H21+H24+H25+H26+H27+H28+H29 | I31: =I9-I21+I24+I25+I26+I27+I28+I29 | ... L31: =L9-L21+L24+L25+L26+L27+L28+L29
A32: Operating margin % | B32: =B31/B5 | C32: =C31/C5 | D32: =D31/D5 | E32: =E31/E5 | F32: =F31/F5 | G32: =G31/G5 | H32: =H31/H5 | I32: =I31/I5 | ... L32: =L31/L5
A34: EBITDA bridge
A35: + Depreciation & amortization | B35: 320 | C35: 360 | D35: 410 | E35: 480 | F35: 540 | G35: 620 | H35: 720 | I35: 820 | J35: 920 | K35: 1010 | L35: 1090
A36: + Net interest (add back if income, subtract if expense) | B36: =-B20 | C36: =-C20 | D36: =-D20 | E36: =-E20 | F36: =-F20 | G36: =-G20 | H36: =-H20 | I36: =-I20 | ... L36: =-L20
A37: EBIT (= Op profit + net interest) | B37: =B31+B36 | C37: =C31+C36 | D37: =D31+D36 | E37: =E31+E36 | F37: =F31+F36 | G37: =G31+G36 | H37: =H31+H36 | I37: =I31+I36 | ... L37: =L31+L36
A38: EBIT margin % | B38: =B37/B5 | C38: =C37/C5 | D38: =D37/D5 | E38: =E37/E5 | F38: =F37/F5 | G38: =G37/G5 | H38: =H37/H5 | I38: =I37/I5 | ... L38: =L37/L5
A39: EBITDA (= EBIT + D&A) | B39: =B37+B35 | C39: =C37+C35 | D39: =D37+D35 | E39: =E37+E35 | F39: =F37+F35 | G39: =G37+G35 | H39: =H37+H35 | I39: =I37+I35 | ... L39: =L37+L35
A40: EBITDA margin % | B40: =B39/B5 | C40: =C39/C5 | D40: =D39/D5 | E40: =E39/E5 | F40: =F39/F5 | G40: =G39/G5 | H40: =H39/H5 | I40: =I39/I5 | ... L40: =L39/L5
A42: Non-operating income | B42: 4.7 | C42: 13.4 | D42: 12.7 | E42: 17.5 | F42: 16.6 | G42: 16.4 | H42: 15 | I42: 15 | J42: 15 | K42: 15 | L42: 15
A43: Non-operating expense | B43: 1.7 | C43: 1.5 | D43: 1.9 | E43: 2.3 | F43: 2.6 | G43: 28.1 | H43: 10 | I43: 10 | J43: 10 | K43: 10 | L43: 10
A44: Pre-tax income (利润总额) | B44: =B31+B42-B43 | C44: =C31+C42-C43 | D44: =D31+D42-D43 | E44: =E31+E42-E43 | F44: =F31+F42-F43 | G44: =G31+G42-G43 | H44: =H31+H42-H43 | I44: =I31+I42-I43 | ... L44: =L31+L42-L43
A45: Income tax expense | B45: 347.9 | C45: 369.3 | D45: 279.8 | E45: 326.3 | F45: 288.1 | G45: 292.3 | H45: =H44*0.115 | I45: =I44*0.115 | J45: =J44*0.12 | K45: =K44*0.12 | L45: =L44*0.125
A46: Effective tax rate % | B46: =B45/B44 | C46: =C45/C44 | D46: =D45/D44 | E46: =E45/E44 | F46: =F45/F44 | G46: =G45/G44 | H46: =H45/H44 | I46: =I45/I44 | ... L46: =L45/L44
A48: Net income (净利润) | B48: =B44-B45 | C48: =C44-C45 | D48: =D44-D45 | E48: =E44-E45 | F48: =F44-F45 | G48: =G44-G45 | H48: =H44-H45 | I48: =I44-I45 | ... L48: =L44-L45
A49: Net margin % | B49: =B48/B5 | C49: =C48/C5 | D49: =D48/D5 | E49: =E48/E5 | F49: =F48/F5 | G49: =G48/G5 | H49: =H48/H5 | I49: =I48/I5 | ... L49: =L48/L5
...

Sheet Cash Flow
A1: HENGLI HYDRAULICS — CONSOLIDATED CASH FLOW (RMB millions)
B3: FY2020A | C3: FY2021A | D3: FY2022A | E3: FY2023A | F3: FY2024A | G3: FY2025A | H3: FY2026E | I3: FY2027E | J3: FY2028E | K3: FY2029E | L3: FY2030E
A5: OPERATING ACTIVITIES
A6: Net income (from IS) | B6: ='Income Statement'!B48 | C6: ='Income Statement'!C48 | D6: ='Income Statement'!D48 | E6: ='Income Statement'!E48 | F6: ='Income Statement'!F48 | G6: ='Income Statement'!G48 | H6: ='Income Statement'!H48 | I6: ='Income Statement'!I48 | ... L6: ='Income Statement'!L48
A7: + D&A (from IS) | B7: ='Income Statement'!B35 | C7: ='Income Statement'!C35 | D7: ='Income Statement'!D35 | E7: ='Income Statement'!E35 | F7: ='Income Statement'!F35 | G7: ='Income Statement'!G35 | H7: ='Income Statement'!H35 | I7: ='Income Statement'!I35 | ... L7: ='Income Statement'!L35
A8: + Working capital changes | B8: -767.9 | C8: -239.5 | D8: -270.7 | E8: 125 | F8: -167.8 | G8: -1348.1 | H8: -280 | I8: -260 | J8: -310 | K8: -290 | L8: -270
A9: + Other non-cash adjustments (SBC, impair, taxes paid timing) | B9: 0 | C9: 0 | D9: 0 | E9: 0 | F9: 0 | G9: 0 | H9: 80 | I9: 90 | J9: 100 | K9: 100 | L9: 100
A10: Cash from operations (CFO) | B10: 1980.6 | C10: 2795.7 | D10: 2063.6 | E10: 2677.1 | F10: 2479 | G10: 1810.9 | H10: =H6+H7+H8+H9 | I10: =I6+I7+I8+I9 | J10: =J6+J7+J8+J9 | K10: =K6+K7+K8+K9 | L10: =L6+L7+L8+L9
A12: INVESTING ACTIVITIES
A13: Capital expenditures (PP&E + intangibles) | B13: -401.1 | C13: -562.4 | D13: -798.8 | E13: -1365.9 | F13: -1071.4 | G13: -924.2 | H13: =-'Income Statement'!H5*0.08 | I13: =-'Income Statement'!I5*0.07 | J13: =-'Income Statement'!J5*0.06 | K13: =-'Income Statement'!K5*0.055 | L13: =-'Income Statement'!L5*0.05
A14: Other investing (financial-product purchases net, M&A) | B14: -261.9 | C14: -370 | D14: 719.2 | E14: -1685.4 | F14: -2028.6 | G14: 66.8 | H14: -200 | I14: -150 | J14: -100 | K14: -100 | L14: -100
A15: Cash from investing (CFI) | B15: =B13+B14 | C15: =C13+C14 | D15: =D13+D14 | E15: =E13+E14 | F15: =F13+F14 | G15: =G13+G14 | H15: =H13+H14 | I15: =I13+I14 | ... L15: =L13+L14
A17: FREE CASH FLOW (CFO - CapEx) | B17: =B10+B13 | C17: =C10+C13 | D17: =D10+D13 | E17: =E10+E13 | F17: =F10+F13 | G17: =G10+G13 | H17: =H10+H13 | I17: =I10+I13 | ... L17: =L10+L13
A18: FCF margin % | B18: =B17/'Income Statement'!B5 | C18: =C17/'Income Statement'!C5 | D18: =D17/'Income Statement'!D5 | E18: =E17/'Income Statement'!E5 | F18: =F17/'Income Statement'!F5 | G18: =G17/'Income Statement'!G5 | H18: =H17/'Income Statement'!H5 | I18: =I17/'Income Statement'!I5 | ... L18: =L17/'Income Statement'!L5
A20: FINANCING ACTIVITIES
A21: Debt issuance / (repayment), net | B21: -361.2 | C21: -286.1 | D21: -313.5 | E21: -126.2 | F21: -185 | G21: 43 | H21: 0 | I21: 0 | J21: 0 | K21: 0 | L21: 0
A22: Dividends paid | B22: -371.9 | C22: -583 | D22: -740.7 | E22: -748.7 | F22: -603.2 | G22: -906.4 | H22: =-'Income Statement'!H58*'Income Statement'!H53 | I22: =-'Income Statement'!I58*'Income Statement'!I53 | J22: =-'Income Statement'!J58*'Income Statement'!J53 | K22: =-'Income Statement'!K58*'Income Statement'!K53 | L22: =-'Income Statement'!L58*'Income Statement'!L53
A23: Other financing (incl. 2022 private placement RMB 2.0bn) | B23: -85.2 | C23: 155.4 | D23: 2003.5 | E23: -5.3 | F23: 0.5 | G23: -0.6 | H23: -50 | I23: -50 | J23: -50 | K23: -50 | L23: -50
A24: Cash from financing (CFF) | B24: =B21+B22+B23 | C24: =C21+C22+C23 | D24: =D21+D22+D23 | E24: =E21+E22+E23 | F24: =F21+F22+F23 | G24: =G21+G22+G23 | H24: =H21+H22+H23 | I24: =I21+I22+I23 | ... L24: =L21+L22+L23
A26: FX impact on cash | B26: -163.9 | C26: -125 | D26: 326.5 | E26: 180.8 | F26: -264.3 | G26: -64.8 | H26: -30 | I26: -20 | J26: -20 | K26: -20 | L26: -20
A27: Net change in cash | B27: =B10+B15+B24+B26 | C27: =C10+C15+C24+C26 | D27: =D10+D15+D24+D26 | E27: =E10+E15+E24+E26 | F27: =F10+F15+F24+F26 | G27: =G10+G15+G24+G26 | H27: =H10+H15+H24+H26 | I27: =I10+I15+I24+I26 | ... L27: =L10+L15+L24+L26
A28: Beginning cash | B28: 2239 | C28: 2574.2 | D28: 3598.8 | E28: 6858.7 | F28: 5785.2 | G28: 4112.1 | H28: =G29 | I28: =H29 | J28: =I29 | K28: =J29 | L28: =K29
A29: Ending cash | B29: =B28+B27 | C29: =C28+C27 | D29: =D28+D27 | E29: =E28+E27 | F29: =F28+F27 | G29: =G28+G27 | H29: =H28+H27 | I29: =I28+I27 | ... L29: =L28+L27
A30: Memo: reported end cash (audited, where avail.) | B30: 2574.2 | C30: 3598.8 | D30: 6858.7 | E30: 5785.2 | F30: 4112.1 | G30: 4136.7

Sheet Balance Sheet
A1: HENGLI HYDRAULICS — CONSOLIDATED BALANCE SHEET (RMB millions)
B3: FY2020A | C3: FY2021A | D3: FY2022A | E3: FY2023A | F3: FY2024A | G3: FY2025A | H3: FY2026E | I3: FY2027E | J3: FY2028E | K3: FY2029E | L3: FY2030E
A5: ASSETS
A6: Current assets
A7: Cash & equivalents | D7: 6886.2 | E7: 8124.3 | F7: 7882.8 | G7: 8871.4 | H7: ='Cash Flow'!H29+4734 | I7: ='Cash Flow'!I29+4734 | J7: ='Cash Flow'!J29+4734 | K7: ='Cash Flow'!K29+4734 | L7: ='Cash Flow'!L29+4734
A8: Trading financial assets | D8: 470.3 | E8: 79.3 | F8: 1027.6 | G8: 345 | H8: 600 | I8: 600 | J8: 600 | K8: 600 | L8: 600
A9: Bills receivable | D9: 480.7 | E9: 427.5 | F9: 601.8 | G9: 529.6 | H9: ='Income Statement'!H5*0.05 | I9: ='Income Statement'!I5*0.05 | J9: ='Income Statement'!J5*0.05 | K9: ='Income Statement'!K5*0.05 | L9: ='Income Statement'!L5*0.05
A10: Accounts receivable | D10: 1111.9 | E10: 1245.1 | F10: 1371.2 | G10: 1910.2 | H10: ='Income Statement'!H5*62.0/365 | I10: ='Income Statement'!I5*60.0/365 | J10: ='Income Statement'!J5*58.0/365 | K10: ='Income Statement'!K5*58.0/365 | L10: ='Income Statement'!L5*58.0/365
A11: Receivables financing (银承汇票池) | D11: 1389.4 | E11: 1094.7 | F11: 783.4 | G11: 829.5 | H11: 900 | I11: 900 | J11: 900 | K11: 900 | L11: 900
A12: Prepayments | D12: 141.4 | E12: 155.7 | F12: 156.5 | G12: 252.2 | H12: ='Income Statement'!H8*0.04 | I12: ='Income Statement'!I8*0.04 | J12: ='Income Statement'!J8*0.04 | K12: ='Income Statement'!K8*0.04 | L12: ='Income Statement'!L8*0.04
A13: Other receivables | D13: 27.9 | E13: 30.4 | F13: 29 | G13: 31.8 | H13: 35 | I13: 35 | J13: 35 | K13: 35 | L13: 35
A14: Inventory | D14: 1765.5 | E14: 1692.1 | F14: 1764.5 | G14: 2154.2 | H14: ='Income Statement'!H8*120.0/365 | I14: ='Income Statement'!I8*118.0/365 | J14: ='Income Statement'!J8*115.0/365 | K14: ='Income Statement'!K8*115.0/365 | L14: ='Income Statement'!L8*115.0/365
A15: Contract assets | D15: 8.9 | E15: 16.1 | F15: 20.4 | G15: 25.8 | H15: 30 | I15: 30 | J15: 30 | K15: 30 | L15: 30
A16: Other current assets | D16: 44.4 | E16: 129.2 | F16: 193.2 | G16: 274.1 | H16: 300 | I16: 300 | J16: 300 | K16: 300 | L16: 300
A17: Total current assets | B17: =B7+B8+B9+B10+B11+B12+B13+B14+B15+B16 | C17: =C7+C8+C9+C10+C11+C12+C13+C14+C15+C16 | D17: =D7+D8+D9+D10+D11+D12+D13+D14+D15+D16 | E17: =E7+E8+E9+E10+E11+E12+E13+E14+E15+E16 | F17: =F7+F8+F9+F10+F11+F12+F13+F14+F15+F16 | G17: =G7+G8+G9+G10+G11+G12+G13+G14+G15+G16 | H17: =H7+H8+H9+H10+H11+H12+H13+H14+H15+H16 | I17: =I7+I8+I9+I10+I11+I12+I13+I14+I15+I16 | ... L17: =L7+L8+L9+L10+L11+L12+L13+L14+L15+L16
A19: Non-current assets
A20: PP&E, net | D20: 2826 | E20: 3344 | F20: 3889.1 | G20: 4997.6 | H20: =G20+(-'Cash Flow'!H13)*0.8-'Income Statement'!H35*0.85 | I20: =H20+(-'Cash Flow'!I13)*0.8-'Income Statement'!I35*0.85 | J20: =I20+(-'Cash Flow'!J13)*0.8-'Income Statement'!J35*0.85 | K20: =J20+(-'Cash Flow'!K13)*0.8-'Income Statement'!K35*0.85 | L20: =K20+(-'Cash Flow'!L13)*0.8-'Income Statement'!L35*0.85
A21: Construction in progress | D21: 450 | E21: 1100 | F21: 1083.7 | G21: 417.2 | H21: 500 | I21: 500 | J21: 500 | K21: 500 | L21: 500
A22: Intangible assets | D22: 420 | E22: 430 | F22: 438.7 | G22: 450.7 | H22: =G22+(-'Cash Flow'!H13)*0.2-'Income Statement'!H35*0.15 | I22: =H22+(-'Cash Flow'!I13)*0.2-'Income Statement'!I35*0.15 | J22: =I22+(-'Cash Flow'!J13)*0.2-'Income Statement'!J35*0.15 | K22: =J22+(-'Cash Flow'!K13)*0.2-'Income Statement'!K35*0.15 | L22: =K22+(-'Cash Flow'!L13)*0.2-'Income Statement'!L35*0.15
A23: Goodwill | D23: 0.7 | E23: 0.7 | F23: 0.7 | G23: 0.7 | H23: =G23 | I23: =H23 | J23: =I23 | K23: =J23 | L23: =K23
A24: LT equity investments | D24: 5 | E24: 6 | F24: 8.4 | G24: 10 | H24: =G24*1.05 | I24: =H24*1.05 | J24: =I24*1.05 | K24: =J24*1.05 | L24: =K24*1.05
A25: Deferred tax assets | D25: 80 | E25: 110 | F25: 138.7 | G25: 275.9 | H25: =G25*1.1 | I25: =H25*1.1 | J25: =I25*1.1 | K25: =J25*1.1 | L25: =K25*1.1
A26: Other non-current assets | D26: 388 | E26: 1053 | F26: 248.7 | G26: 295.8 | H26: 320 | I26: 320 | J26: 320 | K26: 320 | L26: 320
A27: Total non-current assets | B27: =B20+B21+B22+B23+B24+B25+B26 | C27: =C20+C21+C22+C23+C24+C25+C26 | D27: =D20+D21+D22+D23+D24+D25+D26 | E27: =E20+E21+E22+E23+E24+E25+E26 | F27: =F20+F21+F22+F23+F24+F25+F26 | G27: =G20+G21+G22+G23+G24+G25+G26 | H27: =H20+H21+H22+H23+H24+H25+H26 | I27: =I20+I21+I22+I23+I24+I25+I26 | ... L27: =L20+L21+L22+L23+L24+L25+L26
A29: TOTAL ASSETS | B29: =B17+B27 | C29: =C17+C27 | D29: =D17+D27 | E29: =E17+E27 | F29: =F17+F27 | G29: =G17+G27 | H29: =H17+H27 | I29: =I17+I27 | ... L29: =L17+L27
A31: LIABILITIES
A32: Current liabilities
A33: Short-term borrowings | D33: 200 | E33: 100 | F33: 15.4 | G33: 13.5 | H33: 15 | I33: 15 | J33: 15 | K33: 15 | L33: 15
A34: Bills payable | D34: 250 | E34: 300 | F34: 246.6 | G34: 0.8 | H34: 50 | I34: 50 | J34: 50 | K34: 50 | L34: 50
A35: Accounts payable | D35: 1100 | E35: 1200 | F35: 888.9 | G35: 1022.5 | H35: ='Income Statement'!H8*55.0/365 | I35: ='Income Statement'!I8*55.0/365 | J35: ='Income Statement'!J8*55.0/365 | K35: ='Income Statement'!K8*55.0/365 | L35: ='Income Statement'!L8*55.0/365
A36: Contract liabilities (customer advances) | D36: 200 | E36: 250 | F36: 283.6 | G36: 323.8 | H36: ='Income Statement'!H5*0.03 | I36: ='Income Statement'!I5*0.03 | J36: ='Income Statement'!J5*0.03 | K36: ='Income Statement'!K5*0.03 | L36: ='Income Statement'!L5*0.03
A37: Employee comp payable | D37: 250 | E37: 270 | F37: 294.4 | G37: 382 | H37: ='Income Statement'!H5*0.04 | I37: ='Income Statement'!I5*0.04 | J37: ='Income Statement'!J5*0.04 | K37: ='Income Statement'!K5*0.04 | L37: ='Income Statement'!L5*0.04
A38: Tax payable | D38: 140 | E38: 150 | F38: 160.3 | G38: 231.1 | H38: ='Income Statement'!H45*0.65 | I38: ='Income Statement'!I45*0.65 | J38: ='Income Statement'!J45*0.65 | K38: ='Income Statement'!K45*0.65 | L38: ='Income Statement'!L45*0.65
A39: Other payables (incl. dividend payable) | D39: 1200 | E39: 1300 | F39: 1116.2 | G39: 1555.7 | H39: 1600 | I39: 1600 | J39: 1600 | K39: 1600 | L39: 1600
A40: Other current liabilities | D40: 196.2 | E40: 132.5 | F40: 374.7 | G40: 291.1 | H40: 300 | I40: 300 | J40: 300 | K40: 300 | L40: 300
A41: Total current liabilities | B41: =B33+B34+B35+B36+B37+B38+B39+B40 | C41: =C33+C34+C35+C36+C37+C38+C39+C40 | D41: =D33+D34+D35+D36+D37+D38+D39+D40 | E41: =E33+E34+E35+E36+E37+E38+E39+E40 | F41: =F33+F34+F35+F36+F37+F38+F39+F40 | G41: =G33+G34+G35+G36+G37+G38+G39+G40 | H41: =H33+H34+H35+H36+H37+H38+H39+H40 | I41: =I33+I34+I35+I36+I37+I38+I39+I40 | ... L41: =L33+L34+L35+L36+L37+L38+L39+L40
A43: Non-current liabilities
A44: Long-term borrowings | D44: 0 | E44: 0 | F44: 0 | G44: 20 | H44: 20 | I44: 20 | J44: 20 | K44: 20 | L44: 20
A45: Lease liabilities | D45: 0 | E45: 0 | F45: 1.2 | G45: 11.1 | H45: 15 | I45: 15 | J45: 15 | K45: 15 | L45: 15
A46: Deferred revenue (govt grants) | D46: 61.9 | E46: 53.7 | F46: 211.5 | G46: 253.4 | H46: 280 | I46: 280 | J46: 280 | K46: 280 | L46: 280
...

Sheet Scenarios
A1: HENGLI HYDRAULICS — SCENARIO ANALYSIS (FY2030E)
B3: Bull | C3: Base | D3: Bear
A5: KEY ASSUMPTIONS (FY2025A → FY2030E)
A6: Revenue CAGR (FY25-FY30) | B6: 0.18 | C6: 0.13 | D6: 0.07
A7: FY2030E revenue (RMB m) | B7: =10941.0*(1+B6)^5 | C7: =10941.0*(1+C6)^5 | D7: =10941.0*(1+D6)^5
A8: Gross margin FY30E | B8: 0.45 | C8: 0.435 | D8: 0.405
A9: EBITDA margin FY30E | B9: 0.335 | C9: 0.305 | D9: 0.26
A10: Net margin FY30E | B10: 0.27 | C10: 0.245 | D10: 0.205
A11: CapEx as % of revenue | B11: 0.045 | C11: 0.05 | D11: 0.06
A12: WC drag (% of revenue growth) | B12: 0.1 | C12: 0.15 | D12: 0.22
A13: Linear-drive revenue FY30E (RMB m) | B13: 4500 | C13: 2300 | D13: 800
A14: Linear-drive gross margin FY30E | B14: 0.28 | C14: 0.22 | D14: 0.15
A17: FY2030E OUTPUTS
A18: Revenue FY30E | B18: =B7 | C18: =C7 | D18: =D7
A19: Gross profit FY30E | B19: =B7*B8 | C19: =C7*C8 | D19: =D7*D8
A20: EBITDA FY30E | B20: =B7*B9 | C20: =C7*C9 | D20: =D7*D9
A21: Net income FY30E | B21: =B7*B10 | C21: =C7*C10 | D21: =D7*D10
A22: FCF FY30E (approx: EBITDA - CapEx - tax) | B22: =B7*B9-B7*B11-B7*B10*0.13 | C22: =C7*C9-C7*C11-C7*C10*0.13 | D22: =D7*D9-D7*D11-D7*D10*0.13
A23: EPS FY30E (NI / 1,340.8m shares) | B23: =B7*B10/1340.8 | C23: =C7*C10/1340.8 | D23: =D7*D10/1340.8
A26: Cumulative FCF FY2026-FY2030E (RMB m) | B26: 9500 | C26: 6800 | D26: 3800
A28: SCENARIO RATIONALE
A29: Bull | B29: Excavator up-cycle 2026-2028 + linear-drive humanoid wild-card hits (Optimus or major Chinese humanoid program qualified-supplier status); Mexico plant ramps to >$300m/yr; pumps & valves share-gain accelerates to 25%+ on Bosch Rexroth retreat. Revenue >$24bn, EBITDA margin 33-34%.
A31: Base | B31: China hydraulics 8% market CAGR; Hengli outperforms at 13% CAGR via continued share gain and linear-drive ramp to ~RMB 2.3bn (mgmt-implied path). Margins stable at 30-31% EBITDA. Revenue ~RMB 20bn by FY30E.
A33: Bear | B33: Cyclical excavator down-cycle returns 2027-28; Caterpillar in-sources >50% cylinder content; linear-drive ramp stalls (no humanoid qualified-supplier); China hydraulics market grows only 3-5%. Revenue ~RMB 15bn, EBITDA margin compresses to 26%.

Sheet DCF Inputs
A1: HENGLI HYDRAULICS — DCF INPUTS (RMB millions)
B3: FY2026E | C3: FY2027E | D3: FY2028E | E3: FY2029E | F3: FY2030E | G3: Terminal
A5: EBIT (from Income Statement) | B5: ='Income Statement'!H37 | C5: ='Income Statement'!I37 | D5: ='Income Statement'!J37 | E5: ='Income Statement'!K37 | F5: ='Income Statement'!L37
A6: Effective tax rate % | B6: 0.115 | C6: 0.115 | D6: 0.12 | E6: 0.12 | F6: 0.125 | G6: 0.125
A7: NOPAT (EBIT × (1-t)) | B7: =B5*(1-B6) | C7: =C5*(1-C6) | D7: =D5*(1-D6) | E7: =E5*(1-E6) | F7: =F5*(1-F6)
A9: + D&A (from IS) | B9: ='Income Statement'!H35 | C9: ='Income Statement'!I35 | D9: ='Income Statement'!J35 | E9: ='Income Statement'!K35 | F9: ='Income Statement'!L35
A10: − CapEx (from CF) | B10: =-'Cash Flow'!H13 | C10: =-'Cash Flow'!I13 | D10: =-'Cash Flow'!J13 | E10: =-'Cash Flow'!K13 | F10: =-'Cash Flow'!L13
A11: − Change in NWC | B11: 280 | C11: 260 | D11: 310 | E11: 290 | F11: 270
A12: UNLEVERED FREE CASH FLOW | B12: =B7+B9-B10-B11 | C12: =C7+C9-C10-C11 | D12: =D7+D9-D10-D11 | E12: =E7+E9-E10-E11 | F12: =F7+F9-F10-F11
A15: TERMINAL & VALUATION INPUTS
A16: Terminal-year revenue (FY30E) | B16: ='Income Statement'!L5
A17: Terminal-year EBITDA (FY30E) | B17: ='Income Statement'!L39
A18: Terminal-year EBIT (FY30E) | B18: ='Income Statement'!L37
A19: Terminal-year UFCF (FY30E) | B19: =F12
A21: Risk-free rate (China 10Y govt, %) | B21: 0.025
A22: Equity risk premium (%) | B22: 0.06
A23: Beta (vs SSE Composite, 2y weekly) | B23: 1.05
A24: Cost of equity (Ke) | B24: =B21+B23*B22
A25: Pre-tax cost of debt (Kd) | B25: 0.035
A26: Effective marginal tax rate | B26: 0.125
A27: After-tax cost of debt | B27: =B25*(1-B26)
A28: Target debt weight | B28: 0.05
A29: Target equity weight | B29: 0.95
A30: WACC | B30: =B29*B24+B28*B27
A31: Terminal growth rate (g) | B31: 0.03
A32: Mid-year convention | B32: Yes
A35: NOTE: These DCF inputs feed Task 3 (Valuation). The Task 3 worksheet will build Enterprise Value via DCF (sum of discounted UFCF + discounted terminal value), with sensitivity table on WACC × terminal growth.
