Workbook

Sheet Revenue Model
A1: HESAI GROUP — REVENUE MODEL | H1: Blue = input
A2: Detailed revenue build by product and geography (RMB thousands) | H2: Black = formula
H3: Green = link
A4: (RMB thousands) | B4: FY22A | C4: FY23A | D4: FY24A | E4: FY25A | F4: FY26E | G4: FY27E | H4: FY28E | I4: FY29E | J4: FY30E
A6: A. REVENUE BUILD BY PRODUCT (Units × ASP)
A7: UNIT SHIPMENTS (thousand)
A8: ADAS — Long-range (AT-series) | B8: 20 | C8: 175 | D8: 410 | E8: 1280 | F8: 2550 | G8: 3800 | H8: 4900 | I8: 5800 | J8: 6700
A9: ADAS — Ultra-thin / Blind-spot (ET, FT) | B9: 5 | C9: 20 | D9: 46 | E9: 101 | F9: 150 | G9: 200 | H9: 300 | I9: 400 | J9: 400
A10: ADAS subtotal (units, thousands) | B10: =SUM(B8:B9) | C10: =SUM(C8:C9) | D10: =SUM(D8:D9) | E10: =SUM(E8:E9) | F10: =SUM(F8:F9) | G10: =SUM(G8:G9) | H10: =SUM(H8:H9) | I10: =SUM(I8:I9) | J10: =SUM(J8:J9)
A11: Robotics — Robotaxi / Robovan (Pandar/OT/QT) | B11: 55 | C11: 25 | D11: 38 | E11: 75 | F11: 130 | G11: 200 | H11: 280 | I11: 360 | J11: 450
A12: Robotics — Humanoid / Quadruped (JT) | B12: 0 | C12: 0 | D12: 1 | E12: 12 | F12: 70 | G12: 200 | H12: 400 | I12: 600 | J12: 800
A13: Robotics — Lawn-mower / Consumer | B13: 0 | C13: 0 | D13: 1 | E13: 100 | F13: 280 | G13: 450 | H13: 600 | I13: 750 | J13: 900
A14: Robotics — Industrial / AGV / Other | B14: 0 | C14: 2 | D14: 5 | E14: 52 | F14: 120 | G14: 200 | H14: 250 | I14: 300 | J14: 350
A15: Robotics subtotal (units, thousands) | B15: =SUM(B11:B14) | C15: =SUM(C11:C14) | D15: =SUM(D11:D14) | E15: =SUM(E11:E14) | F15: =SUM(F11:F14) | G15: =SUM(G11:G14) | H15: =SUM(H11:H14) | I15: =SUM(I11:I14) | J15: =SUM(J11:J14)
A16: TOTAL UNIT SHIPMENTS (thousands) | B16: =B10+B15 | C16: =C10+C15 | D16: =D10+D15 | E16: =E10+E15 | F16: =F10+F15 | G16: =G10+G15 | H16: =H10+H15 | I16: =I10+I15 | J16: =J10+J15
A18: AVG SELLING PRICE (RMB/unit)
A19: ADAS — Long-range ASP (RMB/unit) | B19: 6000 | C19: 5000 | D19: 1900 | E19: 1300 | F19: 1000 | G19: 850 | H19: 760 | I19: 690 | J19: 640
A20: ADAS — Ultra-thin / Blind-spot ASP | B20: 4000 | C20: 3500 | D20: 2200 | E20: 1500 | F20: 1200 | G20: 1050 | H20: 950 | I20: 870 | J20: 800
A21: Robotics — Robotaxi ASP | B21: 18000 | C21: 30000 | D21: 25000 | E21: 8000 | F21: 6500 | G21: 5500 | H21: 4800 | I21: 4200 | J21: 3800
A22: Robotics — Humanoid ASP | B22: 0 | C22: 0 | D22: 18000 | E22: 5500 | F22: 4500 | G22: 4000 | H22: 3500 | I22: 3100 | J22: 2800
A23: Robotics — Lawn-mower ASP | B23: 0 | C23: 0 | D23: 4000 | E23: 2000 | F23: 1600 | G23: 1300 | H23: 1100 | I23: 950 | J23: 850
A24: Robotics — Industrial ASP | B24: 0 | C24: 8000 | D24: 7000 | E24: 3500 | F24: 3000 | G24: 2500 | H24: 2200 | I24: 1900 | J24: 1700
A26: REVENUE BY PRODUCT (RMB thousands)
A27: ADAS — Long-range revenue | B27: =B8*B19 | C27: =C8*C19 | D27: =D8*D19 | E27: =E8*E19 | F27: =F8*F19 | G27: =G8*G19 | H27: =H8*H19 | I27: =I8*I19 | J27: =J8*J19
A28: ADAS — Ultra-thin/Blind-spot revenue | B28: =B9*B20 | C28: =C9*C20 | D28: =D9*D20 | E28: =E9*E20 | F28: =F9*F20 | G28: =G9*G20 | H28: =H9*H20 | I28: =I9*I20 | J28: =J9*J20
A29: ADAS revenue subtotal | B29: =SUM(B27:B28) | C29: =SUM(C27:C28) | D29: =SUM(D27:D28) | E29: =SUM(E27:E28) | F29: =SUM(F27:F28) | G29: =SUM(G27:G28) | H29: =SUM(H27:H28) | I29: =SUM(I27:I28) | J29: =SUM(J27:J28)
A30: Robotics — Robotaxi revenue | B30: =B11*B21 | C30: =C11*C21 | D30: =D11*D21 | E30: =E11*E21 | F30: =F11*F21 | G30: =G11*G21 | H30: =H11*H21 | I30: =I11*I21 | J30: =J11*J21
A31: Robotics — Humanoid revenue | B31: =B12*B22 | C31: =C12*C22 | D31: =D12*D22 | E31: =E12*E22 | F31: =F12*F22 | G31: =G12*G22 | H31: =H12*H22 | I31: =I12*I22 | J31: =J12*J22
A32: Robotics — Lawn-mower revenue | B32: =B13*B23 | C32: =C13*C23 | D32: =D13*D23 | E32: =E13*E23 | F32: =F13*F23 | G32: =G13*G23 | H32: =H13*H23 | I32: =I13*I23 | J32: =J13*J23
A33: Robotics — Industrial revenue | B33: =B14*B24 | C33: =C14*C24 | D33: =D14*D24 | E33: =E14*E24 | F33: =F14*F24 | G33: =G14*G24 | H33: =H14*H24 | I33: =I14*I24 | J33: =J14*J24
A34: Robotics revenue subtotal | B34: =SUM(B30:B33) | C34: =SUM(C30:C33) | D34: =SUM(D30:D33) | E34: =SUM(E30:E33) | F34: =SUM(F30:F33) | G34: =SUM(G30:G33) | H34: =SUM(H30:H33) | I34: =SUM(I30:I33) | J34: =SUM(J30:J33)
A35: Service revenue (design-in, NRE, project-based) | B35: 42000 | C35: 115000 | D35: 115000 | E35: 25000 | F35: 30000 | G35: 35000 | H35: 40000 | I35: 45000 | J35: 50000
A36: Gas-sensor / legacy revenue | B36: 38000 | C36: 27000 | D36: 15400 | E36: 11000 | F36: 9000 | G36: 7500 | H36: 6500 | I36: 5500 | J36: 5000
A37: TOTAL NET REVENUES | B37: =B29+B34+B35+B36 | C37: =C29+C34+C35+C36 | D37: =D29+D34+D35+D36 | E37: =E29+E34+E35+E36 | F37: =F29+F34+F35+F36 | G37: =G29+G34+G35+G36 | H37: =H29+H34+H35+H36 | I37: =I29+I34+I35+I36 | J37: =J29+J34+J35+J36
A38: YoY growth % | B38: n/a | C38: =C37/B37-1 | D38: =D37/C37-1 | E38: =E37/D37-1 | F38: =F37/E37-1 | G38: =G37/F37-1 | H38: =H37/G37-1 | I38: =I37/H37-1 | J38: =J37/I37-1
A39: Implied blended ASP (RMB/unit) | B39: =B37/B16 | C39: =C37/C16 | D39: =D37/D16 | E39: =E37/E16 | F39: =F37/F16 | G39: =G37/G16 | H39: =H37/H16 | I39: =I37/I16 | J39: =J37/J16
A40: Implied blended ASP (US$/unit, @ FX 7.30) | B40: =B37/B16/7.3 | C40: =C37/C16/7.3 | D40: =D37/D16/7.3 | E40: =E37/E16/7.3 | F40: =F37/F16/7.3 | G40: =G37/G16/7.3 | H40: =H37/H16/7.3 | I40: =I37/I16/7.3 | J40: =J37/J16/7.3
A42: B. REVENUE MIX (% of total)
A43: ADAS % of revenue | B43: =B29/B37 | C43: =C29/C37 | D43: =D29/D37 | E43: =E29/E37 | F43: =F29/F37 | G43: =G29/G37 | H43: =H29/H37 | I43: =I29/I37 | J43: =J29/J37
A44: Robotics % of revenue | B44: =B34/B37 | C44: =C34/C37 | D44: =D34/D37 | E44: =E34/E37 | F44: =F34/F37 | G44: =G34/G37 | H44: =H34/H37 | I44: =I34/I37 | J44: =J34/J37
...

Sheet Income Statement
A1: HESAI GROUP — CONSOLIDATED INCOME STATEMENT
A2: GAAP basis, RMB thousands. Historicals tie to 20-F & FY25 6-K (Mar 24 2026).
A4: (RMB thousands) | B4: FY22A | C4: FY23A | D4: FY24A | E4: FY25A | F4: FY26E | G4: FY27E | H4: FY28E | I4: FY29E | J4: FY30E
A6: REVENUE
A7: Product revenue — ADAS lidar | B7: ='Revenue Model'!B29 | C7: ='Revenue Model'!C29 | D7: ='Revenue Model'!D29 | E7: ='Revenue Model'!E29 | F7: ='Revenue Model'!F29 | G7: ='Revenue Model'!G29 | H7: ='Revenue Model'!H29 | I7: ='Revenue Model'!I29 | J7: ='Revenue Model'!J29
A8: Product revenue — Robotics lidar | B8: ='Revenue Model'!B34 | C8: ='Revenue Model'!C34 | D8: ='Revenue Model'!D34 | E8: ='Revenue Model'!E34 | F8: ='Revenue Model'!F34 | G8: ='Revenue Model'!G34 | H8: ='Revenue Model'!H34 | I8: ='Revenue Model'!I34 | J8: ='Revenue Model'!J34
A9: Service revenue + Gas / legacy | B9: ='Revenue Model'!B35+'Revenue Model'!B36 | C9: ='Revenue Model'!C35+'Revenue Model'!C36 | D9: ='Revenue Model'!D35+'Revenue Model'!D36 | E9: ='Revenue Model'!E35+'Revenue Model'!E36 | F9: ='Revenue Model'!F35+'Revenue Model'!F36 | G9: ='Revenue Model'!G35+'Revenue Model'!G36 | H9: ='Revenue Model'!H35+'Revenue Model'!H36 | I9: ='Revenue Model'!I35+'Revenue Model'!I36 | J9: ='Revenue Model'!J35+'Revenue Model'!J36
A10: Total net revenues | B10: ='Revenue Model'!B37 | C10: ='Revenue Model'!C37 | D10: ='Revenue Model'!D37 | E10: ='Revenue Model'!E37 | F10: ='Revenue Model'!F37 | G10: ='Revenue Model'!G37 | H10: ='Revenue Model'!H37 | I10: ='Revenue Model'!I37 | J10: ='Revenue Model'!J37
A11: YoY growth % | B11: n/a | C11: =C10/B10-1 | D11: =D10/C10-1 | E11: =E10/D10-1 | F11: =F10/E10-1 | G11: =G10/F10-1 | H11: =H10/G10-1 | I11: =I10/H10-1 | J11: =J10/I10-1
A13: COST OF REVENUE
A14: Gross margin % (input) | B14: 0.392 | C14: 0.352 | D14: 0.426 | E14: 0.418 | F14: 0.418 | G14: 0.422 | H14: 0.425 | I14: 0.428 | J14: 0.43
A15: Cost of revenues (calc as Rev × (1-GM%)) | B15: =-B10*(1-B14) | C15: =-C10*(1-C14) | D15: =-D10*(1-D14) | E15: =-E10*(1-E14) | F15: =-F10*(1-F14) | G15: =-G10*(1-G14) | H15: =-H10*(1-H14) | I15: =-I10*(1-I14) | J15: =-J10*(1-J14)
A16: COGS breakdown (memo):
A17: Materials / components | B17: -510000 | C17: -850000 | D17: -780000 | E17: -1130000 | F17: -1490000 | G17: -1820000 | H17: -2200000 | I17: -2630000 | J17: -3080000
A18: Manufacturing & overhead | B18: -160000 | C18: -270000 | D18: -300000 | E18: -420000 | F18: -540000 | G18: -660000 | H18: -790000 | I18: -940000 | J18: -1090000
A19: Logistics / shipping / warranty | B19: -60683 | C19: -95611 | D19: -112572 | E19: -212477 | F19: -270000 | G19: -340000 | H19: -420000 | I19: -510000 | J19: -610000
A20: GROSS PROFIT | B20: =B10+B15 | C20: =C10+C15 | D20: =D10+D15 | E20: =E10+E15 | F20: =F10+F15 | G20: =G10+G15 | H20: =H10+H15 | I20: =I10+I15 | J20: =J10+J15
A21: Gross margin % | B21: =B20/B10 | C21: =C20/C10 | D21: =D20/D10 | E21: =E20/E10 | F21: =F20/F10 | G21: =G20/G10 | H21: =H20/H10 | I21: =I20/I10 | J21: =J20/J10
A23: OPERATING EXPENSES
A24: Sales & marketing expense | B24: -104835 | C24: -148798 | D24: -193032 | E24: -191990 | F24: =-F10*F25 | G24: =-G10*G25 | H24: =-H10*H25 | I24: =-I10*I25 | J24: =-J10*J25
A25: S&M as % of revenue | F25: 0.058 | G25: 0.052 | H25: 0.048 | I25: 0.045 | J25: 0.044
A26: S&M as % of revenue (historical calc) | B26: =-B24/B10 | C26: =-C24/C10 | D26: =-D24/D10 | E26: =-E24/E10
A27: General & administrative expense | B27: -201007 | C27: -320144 | D27: -316913 | E27: -288828 | F27: =-F10*F28 | G27: =-G10*G28 | H27: =-H10*H28 | I27: =-I10*I28 | J27: =-J10*J28
A28: G&A as % of revenue | F28: 0.088 | G28: 0.075 | H28: 0.065 | I28: 0.058 | J28: 0.054
A29: G&A as % of revenue (historical calc) | B29: =-B27/B10 | C29: =-C27/C10 | D29: =-D27/D10 | E29: =-E27/E10
A30: Research & development expense | B30: -555179 | C30: -790547 | D30: -855641 | E30: -796940 | F30: =-F10*F31 | G30: =-G10*G31 | H30: =-H10*H31 | I30: =-I10*I31 | J30: =-J10*J31
A31: R&D as % of revenue | F31: 0.22 | G31: 0.19 | H31: 0.17 | I31: 0.155 | J31: 0.142
A32: R&D as % of revenue (historical calc) | B32: =-B30/B10 | C32: =-C30/C10 | D32: =-D30/D10 | E32: =-E30/E10
A33: Other operating income, net | B33: 10817 | C33: 26520 | D33: 276093 | E33: 181415 | F33: 80000 | G33: 60000 | H33: 50000 | I33: 50000 | J33: 50000
A34: Total operating expenses | B34: =B24+B27+B30+B33 | C34: =C24+C27+C30+C33 | D34: =D24+D27+D30+D33 | E34: =E24+E27+E30+E33 | F34: =F24+F27+F30+F33 | G34: =G24+G27+G30+G33 | H34: =H24+H27+H30+H33 | I34: =I24+I27+I30+I33 | J34: =J24+J27+J30+J33
A35: OPERATING INCOME (LOSS) | B35: =B20+B34 | C35: =C20+C34 | D35: =D20+D34 | E35: =E20+E34 | F35: =F20+F34 | G35: =G20+G34 | H35: =H20+H34 | I35: =I20+I34 | J35: =J20+J34
A36: Operating margin % | B36: =B35/B10 | C36: =C35/C10 | D36: =D35/D10 | E36: =E35/E10 | F36: =F35/F10 | G36: =G35/G10 | H36: =H35/H10 | I36: =I35/I10 | J36: =J35/J10
A37: Memo: Depreciation & Amortization | B37: 53634 | C37: 86268 | D37: 131809 | E37: 175000 | F37: 230000 | G37: 290000 | H37: 350000 | I37: 410000 | J37: 470000
A38: EBITDA = OpInc + D&A | B38: =B35+B37 | C38: =C35+C37 | D38: =D35+D37 | E38: =E35+E37 | F38: =F35+F37 | G38: =G35+G37 | H38: =H35+H37 | I38: =I35+I37 | J38: =J35+J37
A39: EBITDA margin % | B39: =B38/B10 | C39: =C38/C10 | D39: =D38/D10 | E39: =E38/E10 | F39: =F38/F10 | G39: =G38/G10 | H39: =H38/H10 | I39: =I38/I10 | J39: =J38/J10
A41: BELOW-THE-LINE
A42: Interest income | B42: 58734 | C42: 99813 | D42: 104401 | E42: 130237 | F42: 165000 | G42: 200000 | H42: 235000 | I42: 270000 | J42: 305000
A43: Interest expense | B43: 0 | C43: -3069 | D43: -12827 | E43: -18923 | F43: -20000 | G43: -22000 | H43: -24000 | I43: -26000 | J43: -28000
A44: Foreign exchange gain (loss), net | B44: 20858 | C44: -452 | D44: 14577 | E44: 2156 | F44: 0 | G44: 0 | H44: 0 | I44: 0 | J44: 0
A45: Other income (expense), net | B45: -2161 | C45: 34 | D45: -2476 | E45: 184566 | F45: 10000 | G45: 10000 | H45: 10000 | I45: 10000 | J45: 10000
...

Sheet Cash Flow
A1: HESAI GROUP — CONSOLIDATED CASH FLOW STATEMENT
A2: RMB thousands. Historicals 22-24 from 20-F; 25 from 6-K disclosure; 26-30E projected.
A4: (RMB thousands) | B4: FY22A | C4: FY23A | D4: FY24A | E4: FY25A | F4: FY26E | G4: FY27E | H4: FY28E | I4: FY29E | J4: FY30E
A6: OPERATING ACTIVITIES
A7: Net income (loss) | B7: ='Income Statement'!B50 | C7: ='Income Statement'!C50 | D7: ='Income Statement'!D50 | E7: ='Income Statement'!E50 | F7: ='Income Statement'!F50 | G7: ='Income Statement'!G50 | H7: ='Income Statement'!H50 | I7: ='Income Statement'!I50 | J7: ='Income Statement'!J50
A8: + Depreciation & amortization | B8: ='Income Statement'!B37 | C8: ='Income Statement'!C37 | D8: ='Income Statement'!D37 | E8: ='Income Statement'!E37 | F8: ='Income Statement'!F37 | G8: ='Income Statement'!G37 | H8: ='Income Statement'!H37 | I8: ='Income Statement'!I37 | J8: ='Income Statement'!J37
A9: + Share-based compensation | B9: ='Income Statement'!B61 | C9: ='Income Statement'!C61 | D9: ='Income Statement'!D61 | E9: ='Income Statement'!E61 | F9: ='Income Statement'!F61 | G9: ='Income Statement'!G61 | H9: ='Income Statement'!H61 | I9: ='Income Statement'!I61 | J9: ='Income Statement'!J61
A10: + Other non-cash adjustments | B10: 37195 | C10: 56171 | D10: 54078 | E10: 30000 | F10: 25000 | G10: 25000 | H10: 25000 | I10: 25000 | J10: 25000
A11: Changes in working capital (input as % of revenue change)
A12: WC change as % of revenue change | B12: -1.46 | C12: -0.04 | D12: -0.55 | E12: -0.18 | F12: -0.2 | G12: -0.15 | H12: -0.12 | I12: -0.1 | J12: -0.08
A13: Δ Working capital (calc) | B13: -200000 | C13: =C12*('Income Statement'!C10-'Income Statement'!B10) | D13: =D12*('Income Statement'!D10-'Income Statement'!C10) | E13: =E12*('Income Statement'!E10-'Income Statement'!D10) | F13: =F12*('Income Statement'!F10-'Income Statement'!E10) | G13: =G12*('Income Statement'!G10-'Income Statement'!F10) | H13: =H12*('Income Statement'!H10-'Income Statement'!G10) | I13: =I12*('Income Statement'!I10-'Income Statement'!H10) | J13: =J12*('Income Statement'!J10-'Income Statement'!I10)
A14: Cash from operating activities | B14: =SUM(B7:B10)+B13 | C14: =SUM(C7:C10)+C13 | D14: =SUM(D7:D10)+D13 | E14: =SUM(E7:E10)+E13 | F14: =SUM(F7:F10)+F13 | G14: =SUM(G7:G10)+G13 | H14: =SUM(H7:H10)+H13 | I14: =SUM(I7:I10)+I13 | J14: =SUM(J7:J10)+J13
A16: INVESTING ACTIVITIES
A17: Capex (purchases of PP&E) | B17: -231210 | C17: -406748 | D17: -259541 | E17: -360000 | F17: -550000 | G17: -700000 | H17: -800000 | I17: -850000 | J17: -900000
A18: Purchases of intangibles | B18: -9180 | C18: -7925 | D18: -11817 | E18: -15000 | F18: -18000 | G18: -20000 | H18: -22000 | I18: -24000 | J18: -26000
A19: Net short-term investments activity | B19: 1392000 | C19: -621566 | D19: 1227234 | E19: -2900000 | F19: -200000 | G19: -250000 | H19: -300000 | I19: -300000 | J19: -300000
A20: Other investing (acquisitions, equity inv.) | B20: -31964 | C20: -24247 | D20: 0 | E20: -2750000 | F20: -100000 | G20: -120000 | H20: -140000 | I20: -160000 | J20: -180000
A21: Cash from investing | B21: =SUM(B17:B20) | C21: =SUM(C17:C20) | D21: =SUM(D17:D20) | E21: =SUM(E17:E20) | F21: =SUM(F17:F20) | G21: =SUM(G17:G20) | H21: =SUM(H17:H20) | I21: =SUM(I17:I20) | J21: =SUM(J17:J20)
A23: FREE CASH FLOW
A24: Free cash flow (CFO + Capex + Intangibles) | B24: =B14+B17+B18 | C24: =C14+C17+C18 | D24: =D14+D17+D18 | E24: =E14+E17+E18 | F24: =F14+F17+F18 | G24: =G14+G17+G18 | H24: =H14+H17+H18 | I24: =I14+I17+I18 | J24: =J14+J17+J18
A25: FCF margin % | B25: =B24/'Income Statement'!B10 | C25: =C24/'Income Statement'!C10 | D25: =D24/'Income Statement'!D10 | E25: =E24/'Income Statement'!E10 | F25: =F24/'Income Statement'!F10 | G25: =G24/'Income Statement'!G10 | H25: =H24/'Income Statement'!H10 | I25: =I24/'Income Statement'!I10 | J25: =J24/'Income Statement'!J10
A27: FINANCING ACTIVITIES
A28: Proceeds from IPO / follow-on equity | B28: 0 | C28: 1225470 | D28: 0 | E28: 4400000 | F28: 0 | G28: 0 | H28: 0 | I28: 0 | J28: 0
A29: Net borrowings (issuance - repayment) | B29: 18472 | C29: 376592 | D29: 216536 | E29: 110000 | F29: 50000 | G29: 50000 | H29: 50000 | I29: 50000 | J29: 50000
A30: Option exercises / other | B30: -3296 | C30: -11626 | D30: 34139 | E30: 25000 | F30: 30000 | G30: 30000 | H30: 30000 | I30: 30000 | J30: 30000
A31: Cash from financing | B31: =SUM(B28:B30) | C31: =SUM(C28:C30) | D31: =SUM(D28:D30) | E31: =SUM(E28:E30) | F31: =SUM(F28:F30) | G31: =SUM(G28:G30) | H31: =SUM(H28:H30) | I31: =SUM(I28:I30) | J31: =SUM(J28:J30)
A33: FX effect on cash | B33: 42000 | C33: 13000 | D33: 15000 | E33: -8000 | F33: 0 | G33: 0 | H33: 0 | I33: 0 | J33: 0
A34: Net change in cash | B34: =B14+B21+B31+B33 | C34: =C14+C21+C31+C33 | D34: =D14+D21+D31+D33 | E34: =E14+E21+E31+E33 | F34: =F14+F21+F31+F33 | G34: =G14+G21+G31+G33 | H34: =H14+H21+H31+H33 | I34: =I14+I21+I31+I33 | J34: =J14+J21+J31+J33
A35: Beginning cash & equivalents | B35: 3110000 | C35: =B35+B34 | D35: =C35+C34 | E35: =D35+D34 | F35: =E35+E34 | G35: =F35+F34 | H35: =G35+G34 | I35: =H35+H34 | J35: =I35+I34
A36: Ending cash & equivalents | B36: =B35+B34 | C36: =C35+C34 | D36: =D35+D34 | E36: =E35+E34 | F36: =F35+F34 | G36: =G35+G34 | H36: =H35+H34 | I36: =I35+I34 | J36: =J35+J34

Sheet Balance Sheet
A1: HESAI GROUP — CONSOLIDATED BALANCE SHEET
A2: RMB thousands as of December 31. Historicals 24/25 from 6-K disclosures; 22/23 from 20-F; 26-30E projected.
A4: (RMB thousands) | B4: FY22A | C4: FY23A | D4: FY24A | E4: FY25A | F4: FY26E | G4: FY27E | H4: FY28E | I4: FY29E | J4: FY30E
A6: CURRENT ASSETS
A7: Cash & equivalents | B7: 2935000 | C7: 2010000 | D7: 2838966 | E7: 1663492 | F7: 1800000 | G7: 2200000 | H7: 2800000 | I7: 3500000 | J7: 4400000
A8: Short-term investments | B8: 600000 | C8: 1700000 | D8: 362195 | E8: 3091856 | F8: 3300000 | G8: 3550000 | H8: 3850000 | I8: 4150000 | J8: 4450000
A9: Accounts receivable, net | B9: 485044 | C9: 524818 | D9: 765027 | E9: 1262220 | F9: 1850000 | G9: 2700000 | H9: 3650000 | I9: 4600000 | J9: 5550000
A10: Inventories | B10: 605000 | C10: 460000 | D10: 482137 | E10: 670453 | F10: 950000 | G10: 1300000 | H10: 1700000 | I10: 2100000 | J10: 2500000
A11: Notes receivable | B11: 0 | C11: 0 | D11: 22341 | E11: 94697 | F11: 130000 | G11: 175000 | H11: 220000 | I11: 270000 | J11: 330000
A12: Prepayments & other current | B12: 110000 | C12: 110000 | D12: 193448 | E12: 282431 | F12: 360000 | G12: 460000 | H12: 580000 | I12: 720000 | J12: 860000
A13: Contract assets + due from related | B13: 12600 | C13: 24727 | D13: 14948 | E13: 0 | F13: 0 | G13: 0 | H13: 0 | I13: 0 | J13: 0
A14: Total current assets | B14: =SUM(B7:B13) | C14: =SUM(C7:C13) | D14: =SUM(D7:D13) | E14: =SUM(E7:E13) | F14: =SUM(F7:F13) | G14: =SUM(G7:G13) | H14: =SUM(H7:H13) | I14: =SUM(I7:I13) | J14: =SUM(J7:J13)
A16: NON-CURRENT ASSETS
A17: Property & equipment, net | B17: 350000 | C17: 650000 | D17: 944218 | E17: 1099283 | F17: 1480000 | G17: 1930000 | H17: 2410000 | I17: 2890000 | J17: 3360000
A18: Long-term investments | B18: 10000 | C18: 25000 | D18: 31798 | E18: 2781670 | F18: 2900000 | G18: 3050000 | H18: 3200000 | I18: 3370000 | J18: 3550000
A19: Intangible assets, net | B19: 40000 | C19: 60000 | D19: 76554 | E19: 95507 | F19: 110000 | G19: 128000 | H19: 148000 | I19: 170000 | J19: 194000
A20: Land-use rights, net | B20: 20000 | C20: 30000 | D20: 39879 | E20: 39015 | F20: 38000 | G20: 37000 | H20: 36000 | I20: 35000 | J20: 34000
A21: Right-of-use assets | B21: 85000 | C21: 100000 | D21: 114260 | E21: 109318 | F21: 110000 | G21: 110000 | H21: 110000 | I21: 110000 | J21: 110000
A22: Other non-current | B22: 70000 | C22: 90000 | D22: 100246 | E22: 67322 | F22: 80000 | G22: 95000 | H22: 110000 | I22: 125000 | J22: 140000
A23: Total non-current assets | B23: =SUM(B17:B22) | C23: =SUM(C17:C22) | D23: =SUM(D17:D22) | E23: =SUM(E17:E22) | F23: =SUM(F17:F22) | G23: =SUM(G17:G22) | H23: =SUM(H17:H22) | I23: =SUM(I17:I22) | J23: =SUM(J17:J22)
A25: TOTAL ASSETS | B25: =B14+B23 | C25: =C14+C23 | D25: =D14+D23 | E25: =E14+E23 | F25: =F14+F23 | G25: =G14+G23 | H25: =H14+H23 | I25: =I14+I23 | J25: =J14+J23
A27: CURRENT LIABILITIES
A28: Short-term borrowings | B28: 0 | C28: 111682 | D28: 345253 | E28: 448233 | F28: 480000 | G28: 520000 | H28: 560000 | I28: 600000 | J28: 640000
A29: Accounts payable | B29: 210000 | C29: 270000 | D29: 345011 | E29: 592560 | F29: 870000 | G29: 1240000 | H29: 1670000 | I29: 2090000 | J29: 2520000
A30: Notes payable | B30: 0 | C30: 7000 | D30: 10096 | E30: 150199 | F30: 200000 | G30: 260000 | H30: 320000 | I30: 380000 | J30: 440000
A31: Contract liabilities (deferred revenue) | B31: 40378 | C31: 79925 | D31: 32994 | E31: 21019 | F31: 28000 | G31: 35000 | H31: 42000 | I31: 50000 | J31: 58000
A32: Accrued warranty liability | B32: 20000 | C32: 30000 | D32: 43607 | E32: 77672 | F32: 105000 | G32: 140000 | H32: 180000 | I32: 220000 | J32: 260000
A33: Accrued expenses & other current | B33: 300000 | C33: 380000 | D33: 516726 | E33: 578495 | F33: 720000 | G33: 900000 | H33: 1100000 | I33: 1320000 | J33: 1550000
A34: Income tax payable + due to related | B34: 0 | C34: 0 | D34: 335253 | E34: 27157 | F34: 30000 | G34: 40000 | H34: 50000 | I34: 60000 | J34: 75000
A35: Total current liabilities | B35: =SUM(B28:B34) | C35: =SUM(C28:C34) | D35: =SUM(D28:D34) | E35: =SUM(E28:E34) | F35: =SUM(F28:F34) | G35: =SUM(G28:G34) | H35: =SUM(H28:H34) | I35: =SUM(I28:I34) | J35: =SUM(J28:J34)
A37: NON-CURRENT LIABILITIES
A38: Long-term borrowings | B38: 25000 | C38: 285000 | D38: 269438 | E38: 278727 | F38: 320000 | G38: 360000 | H38: 400000 | I38: 440000 | J38: 480000
A39: Operating lease liabilities (non-current) | B39: 60000 | C39: 80000 | D39: 98370 | E39: 85555 | F39: 90000 | G39: 95000 | H39: 100000 | I39: 105000 | J39: 110000
A40: Other non-current liabilities | B40: 25000 | C40: 50000 | D40: 61132 | E40: 42907 | F40: 50000 | G40: 60000 | H40: 70000 | I40: 80000 | J40: 90000
A41: Total non-current liabilities | B41: =SUM(B38:B40) | C41: =SUM(C38:C40) | D41: =SUM(D38:D40) | E41: =SUM(E38:E40) | F41: =SUM(F38:F40) | G41: =SUM(G38:G40) | H41: =SUM(H38:H40) | I41: =SUM(I38:I40) | J41: =SUM(J38:J40)
A43: TOTAL LIABILITIES | B43: =B35+B41 | C43: =C35+C41 | D43: =D35+D41 | E43: =E35+E41 | F43: =F35+F41 | G43: =G35+G41 | H43: =H35+H41 | I43: =I35+I41 | J43: =J35+J41
A45: SHAREHOLDERS' EQUITY
A46: Common stock (Class A + Class B) | B46: 80 | C46: 85 | D46: 89 | E46: 107 | F46: 107 | G46: 107 | H46: 107 | I46: 107 | J46: 107
A47: Additional paid-in capital | B47: 6300000 | C47: 7400000 | D47: 7577113 | E47: 11925963 | F47: 11955963 | G47: 11985963 | H47: 12015963 | I47: 12045963 | J47: 12075963
A48: Subscription receivables | B48: 0 | C48: -292721 | D48: -292721 | E48: 0 | F48: 0 | G48: 0 | H48: 0 | I48: 0 | J48: 0
...

Sheet DCF Inputs
A1: HESAI GROUP — DCF INPUTS
A2: Unlevered FCF build for Task 3 valuation. RMB thousands.
A4: (RMB thousands) | B4: FY22A | C4: FY23A | D4: FY24A | E4: FY25A | F4: FY26E | G4: FY27E | H4: FY28E | I4: FY29E | J4: FY30E
A6: PROJECTED UNLEVERED FREE CASH FLOW (RMB thousands)
A7: Net revenue | B7: ='Income Statement'!B10 | C7: ='Income Statement'!C10 | D7: ='Income Statement'!D10 | E7: ='Income Statement'!E10 | F7: ='Income Statement'!F10 | G7: ='Income Statement'!G10 | H7: ='Income Statement'!H10 | I7: ='Income Statement'!I10 | J7: ='Income Statement'!J10
A8: EBIT (Operating income) | B8: ='Income Statement'!B35 | C8: ='Income Statement'!C35 | D8: ='Income Statement'!D35 | E8: ='Income Statement'!E35 | F8: ='Income Statement'!F35 | G8: ='Income Statement'!G35 | H8: ='Income Statement'!H35 | I8: ='Income Statement'!I35 | J8: ='Income Statement'!J35
A9: Tax rate % | B9: ='Income Statement'!B47 | C9: ='Income Statement'!C47 | D9: ='Income Statement'!D47 | E9: ='Income Statement'!E47 | F9: ='Income Statement'!F47 | G9: ='Income Statement'!G47 | H9: ='Income Statement'!H47 | I9: ='Income Statement'!I47 | J9: ='Income Statement'!J47
A10: NOPAT = EBIT × (1-t) | B10: =B8*(1-B9) | C10: =C8*(1-C9) | D10: =D8*(1-D9) | E10: =E8*(1-E9) | F10: =F8*(1-F9) | G10: =G8*(1-G9) | H10: =H8*(1-H9) | I10: =I8*(1-I9) | J10: =J8*(1-J9)
A11: + Depreciation & amortization | B11: ='Income Statement'!B37 | C11: ='Income Statement'!C37 | D11: ='Income Statement'!D37 | E11: ='Income Statement'!E37 | F11: ='Income Statement'!F37 | G11: ='Income Statement'!G37 | H11: ='Income Statement'!H37 | I11: ='Income Statement'!I37 | J11: ='Income Statement'!J37
A12: − Capex | B12: ='Cash Flow'!B17 | C12: ='Cash Flow'!C17 | D12: ='Cash Flow'!D17 | E12: ='Cash Flow'!E17 | F12: ='Cash Flow'!F17 | G12: ='Cash Flow'!G17 | H12: ='Cash Flow'!H17 | I12: ='Cash Flow'!I17 | J12: ='Cash Flow'!J17
A13: − Δ Working capital | B13: ='Cash Flow'!B13 | C13: ='Cash Flow'!C13 | D13: ='Cash Flow'!D13 | E13: ='Cash Flow'!E13 | F13: ='Cash Flow'!F13 | G13: ='Cash Flow'!G13 | H13: ='Cash Flow'!H13 | I13: ='Cash Flow'!I13 | J13: ='Cash Flow'!J13
A14: UNLEVERED FCF | B14: =B10+B11+B12+B13 | C14: =C10+C11+C12+C13 | D14: =D10+D11+D12+D13 | E14: =E10+E11+E12+E13 | F14: =F10+F11+F12+F13 | G14: =G10+G11+G12+G13 | H14: =H10+H11+H12+H13 | I14: =I10+I11+I12+I13 | J14: =J10+J11+J12+J13
A15: UFCF margin % | B15: =B14/'Income Statement'!B10 | C15: =C14/'Income Statement'!C10 | D15: =D14/'Income Statement'!D10 | E15: =E14/'Income Statement'!E10 | F15: =F14/'Income Statement'!F10 | G15: =G14/'Income Statement'!G10 | H15: =H14/'Income Statement'!H10 | I15: =I14/'Income Statement'!I10 | J15: =J14/'Income Statement'!J10
A17: DCF VALUATION ASSUMPTIONS (input)
A18: WACC | B18: 0.115
A19: Risk-free rate (US 10Y) | B19: 0.045
A20: Equity risk premium | B20: 0.055
A21: China country risk premium | B21: 0.02
A22: Beta | B22: 1.45
A23: Cost of equity = Rf + β × (ERP + CRP) | B23: =B19+B22*(B20+B21)
A24: Pre-tax cost of debt | B24: 0.055
A25: Tax rate (long-run) | B25: 0.14
A26: After-tax cost of debt | B26: =B24*(1-B25)
A27: Target debt / (debt + equity) | B27: 0.1
A28: Terminal growth rate (perpetual) | B28: 0.03
A29: Net debt at FY25 (RMB '000) | B29: -3500000
A30: Diluted shares outstanding FY25 (thousands) | B30: 146437
A31: USD/RMB | B31: 7.3

Sheet Scenarios
A1: HESAI GROUP — SCENARIO ANALYSIS
A2: Bull / Base / Bear at FY29E. RMB millions unless noted.
A4: Driver / Output | B4: Bull | C4: Base | D4: Bear
A5: ASSUMPTIONS (FY26E-FY29E)
A6: Total units CAGR FY25-FY29 | B6: 0.6 | C6: 0.5 | D6: 0.38
A7: ADAS attach rate in China by FY29 | B7: 0.45 | C7: 0.35 | D7: 0.25
A8: ADAS ASP decline % per year | B8: -0.12 | C8: -0.15 | D8: -0.2
A9: Robotics unit growth (humanoid takeoff) | B9: 0.85 | C9: 0.65 | D9: 0.4
A10: Gross margin FY29E | B10: 0.45 | C10: 0.43 | D10: 0.36
A11: Operating margin FY29E | B11: 0.15 | C11: 0.12 | D11: 0.05
A12: R&D as % revenue FY29E | B12: 0.13 | C12: 0.155 | D12: 0.18
A13: S&M + G&A as % revenue FY29E | B13: 0.085 | C13: 0.103 | D13: 0.135
A14: Capex % of revenue FY29E | B14: 0.045 | C14: 0.055 | D14: 0.07
A16: FY29E OUTPUTS (RMB millions)
A17: FY29E Revenue (RMB M) | B17: 12500 | C17: 9100 | D17: 5600
A18: FY29E EBITDA (RMB M) | B18: 2280 | C18: 1320 | D18: 480
A19: FY29E EBITDA margin | B19: 0.182 | C19: 0.145 | D19: 0.086
A20: FY29E Net income (RMB M) | B20: 1810 | C20: 1010 | D20: 270
A21: FY29E EPS (RMB, diluted) | B21: 10.71 | C21: 5.97 | D21: 1.62
A22: FY29E FCF (RMB M) | B22: 1450 | C22: 720 | D22: 70
A23: FY29E FCF margin | B23: 0.116 | C23: 0.079 | D23: 0.013
A25: Cumulative FCF FY26-FY29 (RMB M) | B25: 3700 | C25: 1900 | D25: 400
A27: IMPLIED VALUATION (US$ per ADS)
A28: DCF fair value (US$/ADS) | B28: 36.5 | C28: 26.8 | D28: 12.4
A29: Implied 18× FY27 P/E (US$/ADS) | B29: 38.2 | C29: 25.9 | D29: 11.6
A30: Implied 6× FY27 P/Sales (US$/ADS) | B30: 32.1 | C30: 23.4 | D30: 14.2
A32: SCENARIO NARRATIVE
A33: Bull: Hesai meets the upper bound of FY26 guidance (3.5M units) and ADAS attach rates in China reach 45% by FY29 driven by mandated L3 redundancy. Multi-lidar adoption (3-6 lidars/L3+ vehicle) lifts content/vehicle. FMC500 SoC and JT128 monetise the humanoid robotics ramp. Robosense remains the credible #2 but cedes share at premium tier; US OEM design-ins resume after favourable 1260H ruling. Gross margin holds 45% via Gen-4 ASIC + in-house emitters; FY29 revenue RMB 12.5bn / US$1.7bn; FY29 net income RMB 1.8bn / US$248M; trades to 22× '29 P/E.
A34: Base: FY26 shipments land at the midpoint (3.25M units) with ADAS attach in China rising to ~35% by FY29. ASPs compress -15%/yr as Chinese OEM price war persists. JT128 humanoid backlog converts to ~600K units/yr by FY29. Gross margin stable 42-43%; operating leverage drives net margin to ~16%. Top-1 customer concentration eases to <20%. FY29 revenue RMB 9.1bn / US$1.25bn; FY29 net income RMB 1.0bn / US$140M; trades to ~18× '29 P/E.
A35: Bear: China ADAS attach rates plateau at ~25% by FY29 as Tesla-style vision-only stacks gain mind-share; Robosense underprices Hesai on volume bids, compressing ADAS gross margin below 35%. Renewed 1260H listing eliminates US OEM revenue. Lawnmower/humanoid ramps disappoint. FY29 revenue RMB 5.6bn / US$770M; net margin only 5%; market de-rates to 12× P/E given multiple compression risk; downside 45%.

Sheet DCF
A1: HESAI GROUP — DISCOUNTED CASH FLOW VALUATION
A2: RMB thousands. Explicit projection FY26E–FY30E. Terminal value via Gordon perpetuity AND exit-multiple methods.
A4: (RMB thousands) | B4: FY26E | C4: FY27E | D4: FY28E | E4: FY29E | F4: FY30E
A6: UNLEVERED FREE CASH FLOW BUILD
A7: Net revenue | B7: ='DCF Inputs'!F7 | C7: ='DCF Inputs'!G7 | D7: ='DCF Inputs'!H7 | E7: ='DCF Inputs'!I7 | F7: ='DCF Inputs'!J7
A8: EBIT | B8: ='DCF Inputs'!F8 | C8: ='DCF Inputs'!G8 | D8: ='DCF Inputs'!H8 | E8: ='DCF Inputs'!I8 | F8: ='DCF Inputs'!J8
A9: Tax rate | B9: ='DCF Inputs'!F9 | C9: ='DCF Inputs'!G9 | D9: ='DCF Inputs'!H9 | E9: ='DCF Inputs'!I9 | F9: ='DCF Inputs'!J9
A10: NOPAT = EBIT × (1−t) | B10: =B8*(1-B9) | C10: =C8*(1-C9) | D10: =D8*(1-D9) | E10: =E8*(1-E9) | F10: =F8*(1-F9)
A11: + D&A | B11: ='DCF Inputs'!F11 | C11: ='DCF Inputs'!G11 | D11: ='DCF Inputs'!H11 | E11: ='DCF Inputs'!I11 | F11: ='DCF Inputs'!J11
A12: − Capex | B12: ='DCF Inputs'!F12 | C12: ='DCF Inputs'!G12 | D12: ='DCF Inputs'!H12 | E12: ='DCF Inputs'!I12 | F12: ='DCF Inputs'!J12
A13: − Δ working capital | B13: ='DCF Inputs'!F13 | C13: ='DCF Inputs'!G13 | D13: ='DCF Inputs'!H13 | E13: ='DCF Inputs'!I13 | F13: ='DCF Inputs'!J13
A14: UNLEVERED FCF | B14: =B10+B11+B12+B13 | C14: =C10+C11+C12+C13 | D14: =D10+D11+D12+D13 | E14: =E10+E11+E12+E13 | F14: =F10+F11+F12+F13
A15: UFCF margin % | B15: =B14/B7 | C15: =C14/C7 | D15: =D14/D7 | E15: =E14/E7 | F15: =F14/F7
A17: VALUATION ASSUMPTIONS
A18: Risk-free rate (US 10Y) | B18: 0.045
A19: Equity risk premium | B19: 0.055
A20: China country risk premium | B20: 0.01
A21: Beta (HSAI 3Y, regressed vs SPX/HSCI) | B21: 1.35
A22: Pre-tax cost of debt | B22: 0.055
A23: Long-run tax rate | B23: 0.14
A24: Target debt / (debt + equity) | B24: 0.1
A25: Cost of equity = Rf + β × ERP + CRP | B25: =B18+B21*B19+B20
A26: After-tax cost of debt | B26: =B22*(1-B23)
A27: WACC | B27: =(1-B24)*B25+B24*B26
A28: Terminal growth rate g (perpetual) | B28: 0.03
A29: Exit multiple (× FY30E EBITDA) | B29: 10
A30: Diluted shares at FY25 (thousands) | B30: 146437
A31: Cash + ST/LT investments at FY25 ('000) | B31: 7536000
A32: Total debt at FY25 ('000) | B32: 726960
A33: USD/RMB FX rate | B33: 7.3
A34: Current ADS price (US$) | B34: 22.44
A36: DISCOUNTING & PRESENT VALUE
A37: Period (years from FY25) | B37: 1 | C37: 2 | D37: 3 | E37: 4 | F37: 5
A38: Discount factor = 1/(1+WACC)^t | B38: =1/(1+$B$27)^B37 | C38: =1/(1+$B$27)^C37 | D38: =1/(1+$B$27)^D37 | E38: =1/(1+$B$27)^E37 | F38: =1/(1+$B$27)^F37
A39: PV of UFCF | B39: =B14*B38 | C39: =C14*C38 | D39: =D14*D38 | E39: =E14*E38 | F39: =F14*F38
A41: METHOD A: GORDON PERPETUITY TERMINAL VALUE
A42: Sum of PV(UFCF) FY26-FY30 | B42: =SUM(B39:F39)
A43: Terminal year UFCF (FY30E) | B43: =F14
A44: Terminal value (Gordon) = UFCF×(1+g)/(WACC−g) | B44: =B43*(1+B28)/(B27-B28)
A45: PV of Terminal Value (Gordon) | B45: =B44*F38
...

Sheet Sensitivity
A1: HESAI GROUP — DCF SENSITIVITY TABLES
A2: Price per ADS (US$) — Gordon perpetuity (top) & exit multiple (bottom).
A4: Table 1: WACC × Terminal Growth Rate (Gordon)
A5: WACC ↓ / g → | B5: 0.02 | C5: 0.025 | D5: 0.03 | E5: 0.035 | F5: 0.04
A6: 0.09 | B6: =('DCF'!B14/1.090000+'DCF'!C14/1.188100+'DCF'!D14/1.295029+'DCF'!E14/1.411582+'DCF'!F14/1.538624+('DCF'!F14*1.0200/0.070000)/1.538624+'DCF'!B31-'DCF'!B32)/'DCF'!B30/'DCF'!B33 | C6: =('DCF'!B14/1.090000+'DCF'!C14/1.188100+'DCF'!D14/1.295029+'DCF'!E14/1.411582+'DCF'!F14/1.538624+('DCF'!F14*1.0250/0.065000)/1.538624+'DCF'!B31-'DCF'!B32)/'DCF'!B30/'DCF'!B33 | D6: =('DCF'!B14/1.090000+'DCF'!C14/1.188100+'DCF'!D14/1.295029+'DCF'!E14/1.411582+'DCF'!F14/1.538624+('DCF'!F14*1.0300/0.060000)/1.538624+'DCF'!B31-'DCF'!B32)/'DCF'!B30/'DCF'!B33 | E6: =('DCF'!B14/1.090000+'DCF'!C14/1.188100+'DCF'!D14/1.295029+'DCF'!E14/1.411582+'DCF'!F14/1.538624+('DCF'!F14*1.0350/0.055000)/1.538624+'DCF'!B31-'DCF'!B32)/'DCF'!B30/'DCF'!B33 | F6: =('DCF'!B14/1.090000+'DCF'!C14/1.188100+'DCF'!D14/1.295029+'DCF'!E14/1.411582+'DCF'!F14/1.538624+('DCF'!F14*1.0400/0.050000)/1.538624+'DCF'!B31-'DCF'!B32)/'DCF'!B30/'DCF'!B33
A7: 0.1 | B7: =('DCF'!B14/1.100000+'DCF'!C14/1.210000+'DCF'!D14/1.331000+'DCF'!E14/1.464100+'DCF'!F14/1.610510+('DCF'!F14*1.0200/0.080000)/1.610510+'DCF'!B31-'DCF'!B32)/'DCF'!B30/'DCF'!B33 | C7: =('DCF'!B14/1.100000+'DCF'!C14/1.210000+'DCF'!D14/1.331000+'DCF'!E14/1.464100+'DCF'!F14/1.610510+('DCF'!F14*1.0250/0.075000)/1.610510+'DCF'!B31-'DCF'!B32)/'DCF'!B30/'DCF'!B33 | D7: =('DCF'!B14/1.100000+'DCF'!C14/1.210000+'DCF'!D14/1.331000+'DCF'!E14/1.464100+'DCF'!F14/1.610510+('DCF'!F14*1.0300/0.070000)/1.610510+'DCF'!B31-'DCF'!B32)/'DCF'!B30/'DCF'!B33 | E7: =('DCF'!B14/1.100000+'DCF'!C14/1.210000+'DCF'!D14/1.331000+'DCF'!E14/1.464100+'DCF'!F14/1.610510+('DCF'!F14*1.0350/0.065000)/1.610510+'DCF'!B31-'DCF'!B32)/'DCF'!B30/'DCF'!B33 | F7: =('DCF'!B14/1.100000+'DCF'!C14/1.210000+'DCF'!D14/1.331000+'DCF'!E14/1.464100+'DCF'!F14/1.610510+('DCF'!F14*1.0400/0.060000)/1.610510+'DCF'!B31-'DCF'!B32)/'DCF'!B30/'DCF'!B33
A8: 0.105 | B8: =('DCF'!B14/1.105000+'DCF'!C14/1.221025+'DCF'!D14/1.349233+'DCF'!E14/1.490902+'DCF'!F14/1.647447+('DCF'!F14*1.0200/0.085000)/1.647447+'DCF'!B31-'DCF'!B32)/'DCF'!B30/'DCF'!B33 | C8: =('DCF'!B14/1.105000+'DCF'!C14/1.221025+'DCF'!D14/1.349233+'DCF'!E14/1.490902+'DCF'!F14/1.647447+('DCF'!F14*1.0250/0.080000)/1.647447+'DCF'!B31-'DCF'!B32)/'DCF'!B30/'DCF'!B33 | D8: =('DCF'!B14/1.105000+'DCF'!C14/1.221025+'DCF'!D14/1.349233+'DCF'!E14/1.490902+'DCF'!F14/1.647447+('DCF'!F14*1.0300/0.075000)/1.647447+'DCF'!B31-'DCF'!B32)/'DCF'!B30/'DCF'!B33 | E8: =('DCF'!B14/1.105000+'DCF'!C14/1.221025+'DCF'!D14/1.349233+'DCF'!E14/1.490902+'DCF'!F14/1.647447+('DCF'!F14*1.0350/0.070000)/1.647447+'DCF'!B31-'DCF'!B32)/'DCF'!B30/'DCF'!B33 | F8: =('DCF'!B14/1.105000+'DCF'!C14/1.221025+'DCF'!D14/1.349233+'DCF'!E14/1.490902+'DCF'!F14/1.647447+('DCF'!F14*1.0400/0.065000)/1.647447+'DCF'!B31-'DCF'!B32)/'DCF'!B30/'DCF'!B33
A9: 0.11 | B9: =('DCF'!B14/1.110000+'DCF'!C14/1.232100+'DCF'!D14/1.367631+'DCF'!E14/1.518070+'DCF'!F14/1.685058+('DCF'!F14*1.0200/0.090000)/1.685058+'DCF'!B31-'DCF'!B32)/'DCF'!B30/'DCF'!B33 | C9: =('DCF'!B14/1.110000+'DCF'!C14/1.232100+'DCF'!D14/1.367631+'DCF'!E14/1.518070+'DCF'!F14/1.685058+('DCF'!F14*1.0250/0.085000)/1.685058+'DCF'!B31-'DCF'!B32)/'DCF'!B30/'DCF'!B33 | D9: =('DCF'!B14/1.110000+'DCF'!C14/1.232100+'DCF'!D14/1.367631+'DCF'!E14/1.518070+'DCF'!F14/1.685058+('DCF'!F14*1.0300/0.080000)/1.685058+'DCF'!B31-'DCF'!B32)/'DCF'!B30/'DCF'!B33 | E9: =('DCF'!B14/1.110000+'DCF'!C14/1.232100+'DCF'!D14/1.367631+'DCF'!E14/1.518070+'DCF'!F14/1.685058+('DCF'!F14*1.0350/0.075000)/1.685058+'DCF'!B31-'DCF'!B32)/'DCF'!B30/'DCF'!B33 | F9: =('DCF'!B14/1.110000+'DCF'!C14/1.232100+'DCF'!D14/1.367631+'DCF'!E14/1.518070+'DCF'!F14/1.685058+('DCF'!F14*1.0400/0.070000)/1.685058+'DCF'!B31-'DCF'!B32)/'DCF'!B30/'DCF'!B33
A10: 0.115 | B10: =('DCF'!B14/1.115000+'DCF'!C14/1.243225+'DCF'!D14/1.386196+'DCF'!E14/1.545608+'DCF'!F14/1.723353+('DCF'!F14*1.0200/0.095000)/1.723353+'DCF'!B31-'DCF'!B32)/'DCF'!B30/'DCF'!B33 | C10: =('DCF'!B14/1.115000+'DCF'!C14/1.243225+'DCF'!D14/1.386196+'DCF'!E14/1.545608+'DCF'!F14/1.723353+('DCF'!F14*1.0250/0.090000)/1.723353+'DCF'!B31-'DCF'!B32)/'DCF'!B30/'DCF'!B33 | D10: =('DCF'!B14/1.115000+'DCF'!C14/1.243225+'DCF'!D14/1.386196+'DCF'!E14/1.545608+'DCF'!F14/1.723353+('DCF'!F14*1.0300/0.085000)/1.723353+'DCF'!B31-'DCF'!B32)/'DCF'!B30/'DCF'!B33 | E10: =('DCF'!B14/1.115000+'DCF'!C14/1.243225+'DCF'!D14/1.386196+'DCF'!E14/1.545608+'DCF'!F14/1.723353+('DCF'!F14*1.0350/0.080000)/1.723353+'DCF'!B31-'DCF'!B32)/'DCF'!B30/'DCF'!B33 | F10: =('DCF'!B14/1.115000+'DCF'!C14/1.243225+'DCF'!D14/1.386196+'DCF'!E14/1.545608+'DCF'!F14/1.723353+('DCF'!F14*1.0400/0.075000)/1.723353+'DCF'!B31-'DCF'!B32)/'DCF'!B30/'DCF'!B33
A11: 0.12 | B11: =('DCF'!B14/1.120000+'DCF'!C14/1.254400+'DCF'!D14/1.404928+'DCF'!E14/1.573519+'DCF'!F14/1.762342+('DCF'!F14*1.0200/0.100000)/1.762342+'DCF'!B31-'DCF'!B32)/'DCF'!B30/'DCF'!B33 | C11: =('DCF'!B14/1.120000+'DCF'!C14/1.254400+'DCF'!D14/1.404928+'DCF'!E14/1.573519+'DCF'!F14/1.762342+('DCF'!F14*1.0250/0.095000)/1.762342+'DCF'!B31-'DCF'!B32)/'DCF'!B30/'DCF'!B33 | D11: =('DCF'!B14/1.120000+'DCF'!C14/1.254400+'DCF'!D14/1.404928+'DCF'!E14/1.573519+'DCF'!F14/1.762342+('DCF'!F14*1.0300/0.090000)/1.762342+'DCF'!B31-'DCF'!B32)/'DCF'!B30/'DCF'!B33 | E11: =('DCF'!B14/1.120000+'DCF'!C14/1.254400+'DCF'!D14/1.404928+'DCF'!E14/1.573519+'DCF'!F14/1.762342+('DCF'!F14*1.0350/0.085000)/1.762342+'DCF'!B31-'DCF'!B32)/'DCF'!B30/'DCF'!B33 | F11: =('DCF'!B14/1.120000+'DCF'!C14/1.254400+'DCF'!D14/1.404928+'DCF'!E14/1.573519+'DCF'!F14/1.762342+('DCF'!F14*1.0400/0.080000)/1.762342+'DCF'!B31-'DCF'!B32)/'DCF'!B30/'DCF'!B33
A12: 0.13 | B12: =('DCF'!B14/1.130000+'DCF'!C14/1.276900+'DCF'!D14/1.442897+'DCF'!E14/1.630474+'DCF'!F14/1.842435+('DCF'!F14*1.0200/0.110000)/1.842435+'DCF'!B31-'DCF'!B32)/'DCF'!B30/'DCF'!B33 | C12: =('DCF'!B14/1.130000+'DCF'!C14/1.276900+'DCF'!D14/1.442897+'DCF'!E14/1.630474+'DCF'!F14/1.842435+('DCF'!F14*1.0250/0.105000)/1.842435+'DCF'!B31-'DCF'!B32)/'DCF'!B30/'DCF'!B33 | D12: =('DCF'!B14/1.130000+'DCF'!C14/1.276900+'DCF'!D14/1.442897+'DCF'!E14/1.630474+'DCF'!F14/1.842435+('DCF'!F14*1.0300/0.100000)/1.842435+'DCF'!B31-'DCF'!B32)/'DCF'!B30/'DCF'!B33 | E12: =('DCF'!B14/1.130000+'DCF'!C14/1.276900+'DCF'!D14/1.442897+'DCF'!E14/1.630474+'DCF'!F14/1.842435+('DCF'!F14*1.0350/0.095000)/1.842435+'DCF'!B31-'DCF'!B32)/'DCF'!B30/'DCF'!B33 | F12: =('DCF'!B14/1.130000+'DCF'!C14/1.276900+'DCF'!D14/1.442897+'DCF'!E14/1.630474+'DCF'!F14/1.842435+('DCF'!F14*1.0400/0.090000)/1.842435+'DCF'!B31-'DCF'!B32)/'DCF'!B30/'DCF'!B33
A13: 0.14 | B13: =('DCF'!B14/1.140000+'DCF'!C14/1.299600+'DCF'!D14/1.481544+'DCF'!E14/1.688960+'DCF'!F14/1.925415+('DCF'!F14*1.0200/0.120000)/1.925415+'DCF'!B31-'DCF'!B32)/'DCF'!B30/'DCF'!B33 | C13: =('DCF'!B14/1.140000+'DCF'!C14/1.299600+'DCF'!D14/1.481544+'DCF'!E14/1.688960+'DCF'!F14/1.925415+('DCF'!F14*1.0250/0.115000)/1.925415+'DCF'!B31-'DCF'!B32)/'DCF'!B30/'DCF'!B33 | D13: =('DCF'!B14/1.140000+'DCF'!C14/1.299600+'DCF'!D14/1.481544+'DCF'!E14/1.688960+'DCF'!F14/1.925415+('DCF'!F14*1.0300/0.110000)/1.925415+'DCF'!B31-'DCF'!B32)/'DCF'!B30/'DCF'!B33 | E13: =('DCF'!B14/1.140000+'DCF'!C14/1.299600+'DCF'!D14/1.481544+'DCF'!E14/1.688960+'DCF'!F14/1.925415+('DCF'!F14*1.0350/0.105000)/1.925415+'DCF'!B31-'DCF'!B32)/'DCF'!B30/'DCF'!B33 | F13: =('DCF'!B14/1.140000+'DCF'!C14/1.299600+'DCF'!D14/1.481544+'DCF'!E14/1.688960+'DCF'!F14/1.925415+('DCF'!F14*1.0400/0.100000)/1.925415+'DCF'!B31-'DCF'!B32)/'DCF'!B30/'DCF'!B33
A16: Table 2: WACC × Exit Multiple (× FY30E EBITDA)
A17: WACC ↓ / Exit Mult → | B17: 7 | C17: 8 | D17: 9 | E17: 10 | F17: 11 | G17: 12 | H17: 14
A18: 0.09 | B18: =('DCF'!B14/1.090000+'DCF'!C14/1.188100+'DCF'!D14/1.295029+'DCF'!E14/1.411582+'DCF'!F14/1.538624+('DCF'!B55*7.0)/1.538624+'DCF'!B31-'DCF'!B32)/'DCF'!B30/'DCF'!B33 | C18: =('DCF'!B14/1.090000+'DCF'!C14/1.188100+'DCF'!D14/1.295029+'DCF'!E14/1.411582+'DCF'!F14/1.538624+('DCF'!B55*8.0)/1.538624+'DCF'!B31-'DCF'!B32)/'DCF'!B30/'DCF'!B33 | D18: =('DCF'!B14/1.090000+'DCF'!C14/1.188100+'DCF'!D14/1.295029+'DCF'!E14/1.411582+'DCF'!F14/1.538624+('DCF'!B55*9.0)/1.538624+'DCF'!B31-'DCF'!B32)/'DCF'!B30/'DCF'!B33 | E18: =('DCF'!B14/1.090000+'DCF'!C14/1.188100+'DCF'!D14/1.295029+'DCF'!E14/1.411582+'DCF'!F14/1.538624+('DCF'!B55*10.0)/1.538624+'DCF'!B31-'DCF'!B32)/'DCF'!B30/'DCF'!B33 | F18: =('DCF'!B14/1.090000+'DCF'!C14/1.188100+'DCF'!D14/1.295029+'DCF'!E14/1.411582+'DCF'!F14/1.538624+('DCF'!B55*11.0)/1.538624+'DCF'!B31-'DCF'!B32)/'DCF'!B30/'DCF'!B33 | G18: =('DCF'!B14/1.090000+'DCF'!C14/1.188100+'DCF'!D14/1.295029+'DCF'!E14/1.411582+'DCF'!F14/1.538624+('DCF'!B55*12.0)/1.538624+'DCF'!B31-'DCF'!B32)/'DCF'!B30/'DCF'!B33 | H18: =('DCF'!B14/1.090000+'DCF'!C14/1.188100+'DCF'!D14/1.295029+'DCF'!E14/1.411582+'DCF'!F14/1.538624+('DCF'!B55*14.0)/1.538624+'DCF'!B31-'DCF'!B32)/'DCF'!B30/'DCF'!B33
A19: 0.1 | B19: =('DCF'!B14/1.100000+'DCF'!C14/1.210000+'DCF'!D14/1.331000+'DCF'!E14/1.464100+'DCF'!F14/1.610510+('DCF'!B55*7.0)/1.610510+'DCF'!B31-'DCF'!B32)/'DCF'!B30/'DCF'!B33 | C19: =('DCF'!B14/1.100000+'DCF'!C14/1.210000+'DCF'!D14/1.331000+'DCF'!E14/1.464100+'DCF'!F14/1.610510+('DCF'!B55*8.0)/1.610510+'DCF'!B31-'DCF'!B32)/'DCF'!B30/'DCF'!B33 | D19: =('DCF'!B14/1.100000+'DCF'!C14/1.210000+'DCF'!D14/1.331000+'DCF'!E14/1.464100+'DCF'!F14/1.610510+('DCF'!B55*9.0)/1.610510+'DCF'!B31-'DCF'!B32)/'DCF'!B30/'DCF'!B33 | E19: =('DCF'!B14/1.100000+'DCF'!C14/1.210000+'DCF'!D14/1.331000+'DCF'!E14/1.464100+'DCF'!F14/1.610510+('DCF'!B55*10.0)/1.610510+'DCF'!B31-'DCF'!B32)/'DCF'!B30/'DCF'!B33 | F19: =('DCF'!B14/1.100000+'DCF'!C14/1.210000+'DCF'!D14/1.331000+'DCF'!E14/1.464100+'DCF'!F14/1.610510+('DCF'!B55*11.0)/1.610510+'DCF'!B31-'DCF'!B32)/'DCF'!B30/'DCF'!B33 | G19: =('DCF'!B14/1.100000+'DCF'!C14/1.210000+'DCF'!D14/1.331000+'DCF'!E14/1.464100+'DCF'!F14/1.610510+('DCF'!B55*12.0)/1.610510+'DCF'!B31-'DCF'!B32)/'DCF'!B30/'DCF'!B33 | H19: =('DCF'!B14/1.100000+'DCF'!C14/1.210000+'DCF'!D14/1.331000+'DCF'!E14/1.464100+'DCF'!F14/1.610510+('DCF'!B55*14.0)/1.610510+'DCF'!B31-'DCF'!B32)/'DCF'!B30/'DCF'!B33
A20: 0.105 | B20: =('DCF'!B14/1.105000+'DCF'!C14/1.221025+'DCF'!D14/1.349233+'DCF'!E14/1.490902+'DCF'!F14/1.647447+('DCF'!B55*7.0)/1.647447+'DCF'!B31-'DCF'!B32)/'DCF'!B30/'DCF'!B33 | C20: =('DCF'!B14/1.105000+'DCF'!C14/1.221025+'DCF'!D14/1.349233+'DCF'!E14/1.490902+'DCF'!F14/1.647447+('DCF'!B55*8.0)/1.647447+'DCF'!B31-'DCF'!B32)/'DCF'!B30/'DCF'!B33 | D20: =('DCF'!B14/1.105000+'DCF'!C14/1.221025+'DCF'!D14/1.349233+'DCF'!E14/1.490902+'DCF'!F14/1.647447+('DCF'!B55*9.0)/1.647447+'DCF'!B31-'DCF'!B32)/'DCF'!B30/'DCF'!B33 | E20: =('DCF'!B14/1.105000+'DCF'!C14/1.221025+'DCF'!D14/1.349233+'DCF'!E14/1.490902+'DCF'!F14/1.647447+('DCF'!B55*10.0)/1.647447+'DCF'!B31-'DCF'!B32)/'DCF'!B30/'DCF'!B33 | F20: =('DCF'!B14/1.105000+'DCF'!C14/1.221025+'DCF'!D14/1.349233+'DCF'!E14/1.490902+'DCF'!F14/1.647447+('DCF'!B55*11.0)/1.647447+'DCF'!B31-'DCF'!B32)/'DCF'!B30/'DCF'!B33 | G20: =('DCF'!B14/1.105000+'DCF'!C14/1.221025+'DCF'!D14/1.349233+'DCF'!E14/1.490902+'DCF'!F14/1.647447+('DCF'!B55*12.0)/1.647447+'DCF'!B31-'DCF'!B32)/'DCF'!B30/'DCF'!B33 | H20: =('DCF'!B14/1.105000+'DCF'!C14/1.221025+'DCF'!D14/1.349233+'DCF'!E14/1.490902+'DCF'!F14/1.647447+('DCF'!B55*14.0)/1.647447+'DCF'!B31-'DCF'!B32)/'DCF'!B30/'DCF'!B33
A21: 0.11 | B21: =('DCF'!B14/1.110000+'DCF'!C14/1.232100+'DCF'!D14/1.367631+'DCF'!E14/1.518070+'DCF'!F14/1.685058+('DCF'!B55*7.0)/1.685058+'DCF'!B31-'DCF'!B32)/'DCF'!B30/'DCF'!B33 | C21: =('DCF'!B14/1.110000+'DCF'!C14/1.232100+'DCF'!D14/1.367631+'DCF'!E14/1.518070+'DCF'!F14/1.685058+('DCF'!B55*8.0)/1.685058+'DCF'!B31-'DCF'!B32)/'DCF'!B30/'DCF'!B33 | D21: =('DCF'!B14/1.110000+'DCF'!C14/1.232100+'DCF'!D14/1.367631+'DCF'!E14/1.518070+'DCF'!F14/1.685058+('DCF'!B55*9.0)/1.685058+'DCF'!B31-'DCF'!B32)/'DCF'!B30/'DCF'!B33 | E21: =('DCF'!B14/1.110000+'DCF'!C14/1.232100+'DCF'!D14/1.367631+'DCF'!E14/1.518070+'DCF'!F14/1.685058+('DCF'!B55*10.0)/1.685058+'DCF'!B31-'DCF'!B32)/'DCF'!B30/'DCF'!B33 | F21: =('DCF'!B14/1.110000+'DCF'!C14/1.232100+'DCF'!D14/1.367631+'DCF'!E14/1.518070+'DCF'!F14/1.685058+('DCF'!B55*11.0)/1.685058+'DCF'!B31-'DCF'!B32)/'DCF'!B30/'DCF'!B33 | G21: =('DCF'!B14/1.110000+'DCF'!C14/1.232100+'DCF'!D14/1.367631+'DCF'!E14/1.518070+'DCF'!F14/1.685058+('DCF'!B55*12.0)/1.685058+'DCF'!B31-'DCF'!B32)/'DCF'!B30/'DCF'!B33 | H21: =('DCF'!B14/1.110000+'DCF'!C14/1.232100+'DCF'!D14/1.367631+'DCF'!E14/1.518070+'DCF'!F14/1.685058+('DCF'!B55*14.0)/1.685058+'DCF'!B31-'DCF'!B32)/'DCF'!B30/'DCF'!B33
A22: 0.115 | B22: =('DCF'!B14/1.115000+'DCF'!C14/1.243225+'DCF'!D14/1.386196+'DCF'!E14/1.545608+'DCF'!F14/1.723353+('DCF'!B55*7.0)/1.723353+'DCF'!B31-'DCF'!B32)/'DCF'!B30/'DCF'!B33 | C22: =('DCF'!B14/1.115000+'DCF'!C14/1.243225+'DCF'!D14/1.386196+'DCF'!E14/1.545608+'DCF'!F14/1.723353+('DCF'!B55*8.0)/1.723353+'DCF'!B31-'DCF'!B32)/'DCF'!B30/'DCF'!B33 | D22: =('DCF'!B14/1.115000+'DCF'!C14/1.243225+'DCF'!D14/1.386196+'DCF'!E14/1.545608+'DCF'!F14/1.723353+('DCF'!B55*9.0)/1.723353+'DCF'!B31-'DCF'!B32)/'DCF'!B30/'DCF'!B33 | E22: =('DCF'!B14/1.115000+'DCF'!C14/1.243225+'DCF'!D14/1.386196+'DCF'!E14/1.545608+'DCF'!F14/1.723353+('DCF'!B55*10.0)/1.723353+'DCF'!B31-'DCF'!B32)/'DCF'!B30/'DCF'!B33 | F22: =('DCF'!B14/1.115000+'DCF'!C14/1.243225+'DCF'!D14/1.386196+'DCF'!E14/1.545608+'DCF'!F14/1.723353+('DCF'!B55*11.0)/1.723353+'DCF'!B31-'DCF'!B32)/'DCF'!B30/'DCF'!B33 | G22: =('DCF'!B14/1.115000+'DCF'!C14/1.243225+'DCF'!D14/1.386196+'DCF'!E14/1.545608+'DCF'!F14/1.723353+('DCF'!B55*12.0)/1.723353+'DCF'!B31-'DCF'!B32)/'DCF'!B30/'DCF'!B33 | H22: =('DCF'!B14/1.115000+'DCF'!C14/1.243225+'DCF'!D14/1.386196+'DCF'!E14/1.545608+'DCF'!F14/1.723353+('DCF'!B55*14.0)/1.723353+'DCF'!B31-'DCF'!B32)/'DCF'!B30/'DCF'!B33
A23: 0.12 | B23: =('DCF'!B14/1.120000+'DCF'!C14/1.254400+'DCF'!D14/1.404928+'DCF'!E14/1.573519+'DCF'!F14/1.762342+('DCF'!B55*7.0)/1.762342+'DCF'!B31-'DCF'!B32)/'DCF'!B30/'DCF'!B33 | C23: =('DCF'!B14/1.120000+'DCF'!C14/1.254400+'DCF'!D14/1.404928+'DCF'!E14/1.573519+'DCF'!F14/1.762342+('DCF'!B55*8.0)/1.762342+'DCF'!B31-'DCF'!B32)/'DCF'!B30/'DCF'!B33 | D23: =('DCF'!B14/1.120000+'DCF'!C14/1.254400+'DCF'!D14/1.404928+'DCF'!E14/1.573519+'DCF'!F14/1.762342+('DCF'!B55*9.0)/1.762342+'DCF'!B31-'DCF'!B32)/'DCF'!B30/'DCF'!B33 | E23: =('DCF'!B14/1.120000+'DCF'!C14/1.254400+'DCF'!D14/1.404928+'DCF'!E14/1.573519+'DCF'!F14/1.762342+('DCF'!B55*10.0)/1.762342+'DCF'!B31-'DCF'!B32)/'DCF'!B30/'DCF'!B33 | F23: =('DCF'!B14/1.120000+'DCF'!C14/1.254400+'DCF'!D14/1.404928+'DCF'!E14/1.573519+'DCF'!F14/1.762342+('DCF'!B55*11.0)/1.762342+'DCF'!B31-'DCF'!B32)/'DCF'!B30/'DCF'!B33 | G23: =('DCF'!B14/1.120000+'DCF'!C14/1.254400+'DCF'!D14/1.404928+'DCF'!E14/1.573519+'DCF'!F14/1.762342+('DCF'!B55*12.0)/1.762342+'DCF'!B31-'DCF'!B32)/'DCF'!B30/'DCF'!B33 | H23: =('DCF'!B14/1.120000+'DCF'!C14/1.254400+'DCF'!D14/1.404928+'DCF'!E14/1.573519+'DCF'!F14/1.762342+('DCF'!B55*14.0)/1.762342+'DCF'!B31-'DCF'!B32)/'DCF'!B30/'DCF'!B33
A24: 0.13 | B24: =('DCF'!B14/1.130000+'DCF'!C14/1.276900+'DCF'!D14/1.442897+'DCF'!E14/1.630474+'DCF'!F14/1.842435+('DCF'!B55*7.0)/1.842435+'DCF'!B31-'DCF'!B32)/'DCF'!B30/'DCF'!B33 | C24: =('DCF'!B14/1.130000+'DCF'!C14/1.276900+'DCF'!D14/1.442897+'DCF'!E14/1.630474+'DCF'!F14/1.842435+('DCF'!B55*8.0)/1.842435+'DCF'!B31-'DCF'!B32)/'DCF'!B30/'DCF'!B33 | D24: =('DCF'!B14/1.130000+'DCF'!C14/1.276900+'DCF'!D14/1.442897+'DCF'!E14/1.630474+'DCF'!F14/1.842435+('DCF'!B55*9.0)/1.842435+'DCF'!B31-'DCF'!B32)/'DCF'!B30/'DCF'!B33 | E24: =('DCF'!B14/1.130000+'DCF'!C14/1.276900+'DCF'!D14/1.442897+'DCF'!E14/1.630474+'DCF'!F14/1.842435+('DCF'!B55*10.0)/1.842435+'DCF'!B31-'DCF'!B32)/'DCF'!B30/'DCF'!B33 | F24: =('DCF'!B14/1.130000+'DCF'!C14/1.276900+'DCF'!D14/1.442897+'DCF'!E14/1.630474+'DCF'!F14/1.842435+('DCF'!B55*11.0)/1.842435+'DCF'!B31-'DCF'!B32)/'DCF'!B30/'DCF'!B33 | G24: =('DCF'!B14/1.130000+'DCF'!C14/1.276900+'DCF'!D14/1.442897+'DCF'!E14/1.630474+'DCF'!F14/1.842435+('DCF'!B55*12.0)/1.842435+'DCF'!B31-'DCF'!B32)/'DCF'!B30/'DCF'!B33 | H24: =('DCF'!B14/1.130000+'DCF'!C14/1.276900+'DCF'!D14/1.442897+'DCF'!E14/1.630474+'DCF'!F14/1.842435+('DCF'!B55*14.0)/1.842435+'DCF'!B31-'DCF'!B32)/'DCF'!B30/'DCF'!B33
A25: 0.14 | B25: =('DCF'!B14/1.140000+'DCF'!C14/1.299600+'DCF'!D14/1.481544+'DCF'!E14/1.688960+'DCF'!F14/1.925415+('DCF'!B55*7.0)/1.925415+'DCF'!B31-'DCF'!B32)/'DCF'!B30/'DCF'!B33 | C25: =('DCF'!B14/1.140000+'DCF'!C14/1.299600+'DCF'!D14/1.481544+'DCF'!E14/1.688960+'DCF'!F14/1.925415+('DCF'!B55*8.0)/1.925415+'DCF'!B31-'DCF'!B32)/'DCF'!B30/'DCF'!B33 | D25: =('DCF'!B14/1.140000+'DCF'!C14/1.299600+'DCF'!D14/1.481544+'DCF'!E14/1.688960+'DCF'!F14/1.925415+('DCF'!B55*9.0)/1.925415+'DCF'!B31-'DCF'!B32)/'DCF'!B30/'DCF'!B33 | E25: =('DCF'!B14/1.140000+'DCF'!C14/1.299600+'DCF'!D14/1.481544+'DCF'!E14/1.688960+'DCF'!F14/1.925415+('DCF'!B55*10.0)/1.925415+'DCF'!B31-'DCF'!B32)/'DCF'!B30/'DCF'!B33 | F25: =('DCF'!B14/1.140000+'DCF'!C14/1.299600+'DCF'!D14/1.481544+'DCF'!E14/1.688960+'DCF'!F14/1.925415+('DCF'!B55*11.0)/1.925415+'DCF'!B31-'DCF'!B32)/'DCF'!B30/'DCF'!B33 | G25: =('DCF'!B14/1.140000+'DCF'!C14/1.299600+'DCF'!D14/1.481544+'DCF'!E14/1.688960+'DCF'!F14/1.925415+('DCF'!B55*12.0)/1.925415+'DCF'!B31-'DCF'!B32)/'DCF'!B30/'DCF'!B33 | H25: =('DCF'!B14/1.140000+'DCF'!C14/1.299600+'DCF'!D14/1.481544+'DCF'!E14/1.688960+'DCF'!F14/1.925415+('DCF'!B55*14.0)/1.925415+'DCF'!B31-'DCF'!B32)/'DCF'!B30/'DCF'!B33
A28: Table 3: FY25–FY29 Revenue CAGR × FY29E EBITDA Margin
A29: Rev CAGR ↓ / EBITDA% → | B29: 0.1 | C29: 0.13 | D29: 0.15 | E29: 0.18 | F29: 0.22
A30: 0.2 | B30: =(((((3027573*(1+0.2)^4)*0.1)*14)/1.545608)+'DCF'!B31-'DCF'!B32)/'DCF'!B30/'DCF'!B33 | C30: =(((((3027573*(1+0.2)^4)*0.13)*14)/1.545608)+'DCF'!B31-'DCF'!B32)/'DCF'!B30/'DCF'!B33 | D30: =(((((3027573*(1+0.2)^4)*0.15)*14)/1.545608)+'DCF'!B31-'DCF'!B32)/'DCF'!B30/'DCF'!B33 | E30: =(((((3027573*(1+0.2)^4)*0.18)*14)/1.545608)+'DCF'!B31-'DCF'!B32)/'DCF'!B30/'DCF'!B33 | F30: =(((((3027573*(1+0.2)^4)*0.22)*14)/1.545608)+'DCF'!B31-'DCF'!B32)/'DCF'!B30/'DCF'!B33
A31: 0.25 | B31: =(((((3027573*(1+0.25)^4)*0.1)*14)/1.545608)+'DCF'!B31-'DCF'!B32)/'DCF'!B30/'DCF'!B33 | C31: =(((((3027573*(1+0.25)^4)*0.13)*14)/1.545608)+'DCF'!B31-'DCF'!B32)/'DCF'!B30/'DCF'!B33 | D31: =(((((3027573*(1+0.25)^4)*0.15)*14)/1.545608)+'DCF'!B31-'DCF'!B32)/'DCF'!B30/'DCF'!B33 | E31: =(((((3027573*(1+0.25)^4)*0.18)*14)/1.545608)+'DCF'!B31-'DCF'!B32)/'DCF'!B30/'DCF'!B33 | F31: =(((((3027573*(1+0.25)^4)*0.22)*14)/1.545608)+'DCF'!B31-'DCF'!B32)/'DCF'!B30/'DCF'!B33
A32: 0.3 | B32: =(((((3027573*(1+0.3)^4)*0.1)*14)/1.545608)+'DCF'!B31-'DCF'!B32)/'DCF'!B30/'DCF'!B33 | C32: =(((((3027573*(1+0.3)^4)*0.13)*14)/1.545608)+'DCF'!B31-'DCF'!B32)/'DCF'!B30/'DCF'!B33 | D32: =(((((3027573*(1+0.3)^4)*0.15)*14)/1.545608)+'DCF'!B31-'DCF'!B32)/'DCF'!B30/'DCF'!B33 | E32: =(((((3027573*(1+0.3)^4)*0.18)*14)/1.545608)+'DCF'!B31-'DCF'!B32)/'DCF'!B30/'DCF'!B33 | F32: =(((((3027573*(1+0.3)^4)*0.22)*14)/1.545608)+'DCF'!B31-'DCF'!B32)/'DCF'!B30/'DCF'!B33
A33: 0.35 | B33: =(((((3027573*(1+0.35)^4)*0.1)*14)/1.545608)+'DCF'!B31-'DCF'!B32)/'DCF'!B30/'DCF'!B33 | C33: =(((((3027573*(1+0.35)^4)*0.13)*14)/1.545608)+'DCF'!B31-'DCF'!B32)/'DCF'!B30/'DCF'!B33 | D33: =(((((3027573*(1+0.35)^4)*0.15)*14)/1.545608)+'DCF'!B31-'DCF'!B32)/'DCF'!B30/'DCF'!B33 | E33: =(((((3027573*(1+0.35)^4)*0.18)*14)/1.545608)+'DCF'!B31-'DCF'!B32)/'DCF'!B30/'DCF'!B33 | F33: =(((((3027573*(1+0.35)^4)*0.22)*14)/1.545608)+'DCF'!B31-'DCF'!B32)/'DCF'!B30/'DCF'!B33
A34: 0.4 | B34: =(((((3027573*(1+0.4)^4)*0.1)*14)/1.545608)+'DCF'!B31-'DCF'!B32)/'DCF'!B30/'DCF'!B33 | C34: =(((((3027573*(1+0.4)^4)*0.13)*14)/1.545608)+'DCF'!B31-'DCF'!B32)/'DCF'!B30/'DCF'!B33 | D34: =(((((3027573*(1+0.4)^4)*0.15)*14)/1.545608)+'DCF'!B31-'DCF'!B32)/'DCF'!B30/'DCF'!B33 | E34: =(((((3027573*(1+0.4)^4)*0.18)*14)/1.545608)+'DCF'!B31-'DCF'!B32)/'DCF'!B30/'DCF'!B33 | F34: =(((((3027573*(1+0.4)^4)*0.22)*14)/1.545608)+'DCF'!B31-'DCF'!B32)/'DCF'!B30/'DCF'!B33

Sheet Comps
A1: HESAI GROUP — COMPARABLE COMPANIES ANALYSIS
A2: Market data as of 2026-05-15 close. LTM = trailing 12-month; NTM = consensus FY26.
A4: Lidar & Auto-Perception Peers
A5: Company | B5: Ticker | C5: Mkt Cap ($M) | D5: EV ($M) | E5: LTM Rev ($M) | F5: NTM Rev ($M) | G5: EV/Rev LTM | H5: EV/Rev NTM | I5: LTM EBITDA ($M) | J5: EV/EBITDA NTM | K5: NTM EPS ($) | L5: P/E NTM | M5: Rev growth NTM | N5: EBITDA mgn NTM
A6: Robosense | B6: 2498.HK | C6: 2010 | D6: 1530 | E6: 290 | F6: 450 | G6: 5.2758621 | H6: 3.4 | I6: -55 | J6: n/m | K6: -0.18 | L6: n/m | M6: 0.55 | N6: -0.05
A7: Ouster | B7: OUST | C7: 720 | D7: 430 | E7: 185 | F7: 240 | G7: 2.3243243 | H7: 1.7916667 | I7: -45 | J7: n/m | K7: -0.4 | L7: n/m | M7: 0.3 | N7: -0.1
A8: Innoviz | B8: INVZ | C8: 135 | D8: 85 | E8: 55 | F8: 95 | G8: 1.5454545 | H8: 0.89473684 | I8: -75 | J8: n/m | K8: -0.85 | L8: n/m | M8: 0.73 | N8: -0.65
A9: Aeva Tech. | B9: AEVA | C9: 1430 | D9: 1280 | E9: 25 | F9: 65 | G9: 51.2 | H9: 19.692308 | I9: -120 | J9: n/m | K9: -1.35 | L9: n/m | M9: 1.6 | N9: -1.2
A10: Luminar Tech. | B10: LAZR | C10: 280 | D10: 480 | E10: 75 | F10: 95 | G10: 6.4 | H10: 5.0526316 | I10: -180 | J10: n/m | K10: -0.6 | L10: n/m | M10: 0.27 | N10: -0.85
A11: Mobileye | B11: MBLY | C11: 12800 | D11: 11900 | E11: 1760 | F11: 2050 | G11: 6.7613636 | H11: 5.804878 | I11: 220 | J11: 29.02439 | K11: 0.42 | L11: 25 | M11: 0.16 | N11: 0.2
A12: Aptiv | B12: APTV | C12: 16500 | D12: 22000 | E12: 21000 | F12: 22500 | G12: 1.047619 | H12: 0.97777778 | I12: 3100 | J12: 6.1111111 | K12: 6.5 | L12: 13.5 | M12: 0.07 | N12: 0.16
A13: indie Semiconductor | B13: INDI | C13: 320 | D13: 400 | E13: 220 | F13: 310 | G13: 1.8181818 | H13: 1.2903226 | I13: -110 | J13: n/m | K13: -0.55 | M13: 0.41 | N13: -0.18
A14: ON Semiconductor | B14: ON | C14: 24300 | D14: 26500 | E14: 6850 | F14: 7200 | G14: 3.8686131 | H14: 3.6805556 | I14: 2230 | J14: 11.501736 | K14: 3.2 | L14: 18.5 | M14: 0.05 | N14: 0.32
A15: --- Hesai (subject company) ---
A16: Hesai Group | B16: HSAI | C16: 3528 | D16: 2595 | E16: 432.9 | F16: 648.90411 | G16: 5.994456 | H16: 3.99905 | I16: 47.089452 | J16: 33.890255 | K16: 0.3661424 | L16: 61.28763 | M16: 0.5 | N16: 0.118
A18: STATISTICAL SUMMARY — Lidar Pure-plays
A19: Maximum | G19: =MAX(G6:G10) | H19: =MAX(H6:H10) | M19: =MAX(M6:M10) | N19: =MAX(N6:N10)
A20: 75th Percentile | G20: =PERCENTILE(G6:G10,0.75) | H20: =PERCENTILE(H6:H10,0.75) | M20: =PERCENTILE(M6:M10,0.75) | N20: =PERCENTILE(N6:N10,0.75)
A21: Median | G21: =MEDIAN(G6:G10) | H21: =MEDIAN(H6:H10) | M21: =MEDIAN(M6:M10) | N21: =MEDIAN(N6:N10)
A22: 25th Percentile | G22: =PERCENTILE(G6:G10,0.25) | H22: =PERCENTILE(H6:H10,0.25) | M22: =PERCENTILE(M6:M10,0.25) | N22: =PERCENTILE(N6:N10,0.25)
A23: Minimum | G23: =MIN(G6:G10) | H23: =MIN(H6:H10) | M23: =MIN(M6:M10) | N23: =MIN(N6:N10)
A25: STATISTICAL SUMMARY — Adjacent Auto-Tech (MBLY, APTV, INDI, ON)
A26: Maximum | G26: =MAX(G11:G14) | H26: =MAX(H11:H14) | M26: =MAX(M11:M14) | N26: =MAX(N11:N14)
A27: 75th Percentile | G27: =PERCENTILE(G11:G14,0.75) | H27: =PERCENTILE(H11:H14,0.75) | M27: =PERCENTILE(M11:M14,0.75) | N27: =PERCENTILE(N11:N14,0.75)
A28: Median | G28: =MEDIAN(G11:G14) | H28: =MEDIAN(H11:H14) | M28: =MEDIAN(M11:M14) | N28: =MEDIAN(N11:N14)
A29: 25th Percentile | G29: =PERCENTILE(G11:G14,0.25) | H29: =PERCENTILE(H11:H14,0.25) | M29: =PERCENTILE(M11:M14,0.25) | N29: =PERCENTILE(N11:N14,0.25)
A30: Minimum | G30: =MIN(G11:G14) | H30: =MIN(H11:H14) | M30: =MIN(M11:M14) | N30: =MIN(N11:N14)
A33: IMPLIED VALUATION — Apply Peer Multiples to Hesai
A34: NTM Revenue (FY26E, $M) | B34: 648.90411
A35: Apply lidar peer 25%ile EV/Rev NTM | B35: 2
A36: Apply lidar peer Median EV/Rev NTM | B36: 4
A37: Apply lidar peer 75%ile EV/Rev NTM | B37: 6
A38: Implied price / ADS (US$, Bear (2× EV/Rev)) | B38: =(B34*B35+933)/162
A39: Implied price / ADS (US$, Base (4× EV/Rev)) | B39: =(B34*B36+933)/162
A40: Implied price / ADS (US$, Bull (6× EV/Rev)) | B40: =(B34*B37+933)/162
A42: FY27E EPS estimate (US$) | B42: 0.67662931
A43: Apply 25× FY27 P/E (bear) | B43: 25
A44: Apply 32× FY27 P/E (base) | B44: 32
A45: Apply 40× FY27 P/E (bull) | B45: 40
A46: Implied price / ADS (Bear P/E) | B46: =B42*B43
...

Sheet Valuation Summary
A1: HESAI GROUP — VALUATION SUMMARY & PRICE TARGET
A2: Methods, ranges, and weighted price target as of 2026-05-19.
A4: Method | B4: Low (US$) | C4: Base (US$) | D4: High (US$) | E4: Weight | F4: Weighted Base | G4: Notes
A5: DCF — Gordon Perpetuity (g=3%, WACC=11.5%) | B5: 13 | C5: 15.5 | D5: 22.1 | E5: 0.1 | F5: =C5*E5 | G5: Conservative; TV = 85% of EV
A6: DCF — Exit Multiple (10/12/14× FY30E EBITDA) | B6: 24.5 | C6: 30.5 | D6: 38 | E6: 0.25 | F6: =C6*E6 | G6: Mid-cycle exit; FY30E EBITDA RMB 2.4bn / US$331M
A7: Comps — EV/Revenue NTM (3/5/7× $649M) | B7: 19 | C7: 26 | D7: 35 | E7: 0.15 | F7: =C7*E7 | G7: Lidar peer median 5× NTM EV/Rev (Robosense, OUST)
A8: EV/Revenue FY27E (4.5/5.5/6.5× $886M) | B8: 30 | C8: 35.2 | D8: 41 | E8: 0.25 | F8: =C8*E8 | G8: NTM+1 multiple — captures FY27 operating leverage
A9: EV/EBITDA FY28E (13/15/18× $216M) | B9: 22.5 | C9: 25.1 | D9: 29 | E9: 0.15 | F9: =C9*E9 | G9: Premium peer EV/EBITDA; profitable scale tier
A10: Forward P/E FY28E (25/28/32× $1.00 EPS) | B10: 25 | C10: 28.1 | D10: 32 | E10: 0.1 | F10: =C10*E10 | G10: P/E mid-30s for 40%-grower with op leverage
A11: WEIGHTED-AVERAGE PRICE TARGET | E11: =SUM(E5:E10) | F11: =SUM(F5:F10)
A12: Rounded 12-month price target | F12: =ROUND(F11,0)
A13: Current price (2026-05-15) | F13: 22.44
A14: Upside to target | F14: =F11/F13-1
A15: Recommendation | F15: BUY / OVERWEIGHT
A18: FOOTBALL FIELD DATA (for chart)
A19: Method | B19: Low | C19: High | D19: Range
A20: DCF — Gordon Perpetuity (g=3%, WACC=11.5%) | B20: 13 | C20: 22.1 | D20: =C20-B20
A21: DCF — Exit Multiple (10/12/14× FY30E EBITDA) | B21: 24.5 | C21: 38 | D21: =C21-B21
A22: Comps — EV/Revenue NTM (3/5/7× $649M) | B22: 19 | C22: 35 | D22: =C22-B22
A23: EV/Revenue FY27E (4.5/5.5/6.5× $886M) | B23: 30 | C23: 41 | D23: =C23-B23
A24: EV/EBITDA FY28E (13/15/18× $216M) | B24: 22.5 | C24: 29 | D24: =C24-B24
A25: Forward P/E FY28E (25/28/32× $1.00 EPS) | B25: 25 | C25: 32 | D25: =C25-B25
